Workbook

Sheet BRAYAN
A1: CONCEPTO | B1: VALOR | C1: ENERO | D1: FEBRERO | E1: MARZO | F1: ABRIL | G1: MAYO | H1: JUNIO | I1: JULIO | J1: AGOSTO | K1: SEPTIEMBRE | L1: OCTUBRE | M1: NOVIEMBRE | N1: DICIEMBRE | O1: ENERO | P1: FEBRERO | Q1: MARZO | R1: ABRIL | S1: MAYO | T1: JUNIO | U1: JULIO | V1: AGOSTO | W1: SEPTIEMBRE | X1: OCTUBRE | Y1: NOVIEMBRE | Z1: DICIEMBRE | AA1: ENERO | AB1: FEBRERO | AC1: MARZO | AD1: ABRIL | AE1: MAYO | AF1: JUNIO | AG1: JULIO | AH1: AGOSTO | AI1: SEPTIEMBRE | AJ1: OCTUBRE | AK1: NOVIEMBRE | AL1: DICIEMBRE | AM1: ENERO | AN1: FEBRERO | AO1: MARZO | AP1: ABRIL | AQ1: MAYO | AR1: JUNIO | AS1: JULIO | AT1: AGOSTO | AU1: SEPTIEMBRE | AV1: OCTUBRE | AW1: NOVIEMBRE | AX1: DICIEMBRE | AY1: ENERO | AZ1: FEBRERO | BA1: MARZO | BB1: ABRIL | BC1: MAYO | BD1: JUNIO | BE1: JULIO | BF1: AGOSTO | BG1: SEPTIEMBRE | BH1: OCTUBRE | BI1: NOVIEMBRE | BJ1: DICIEMBRE | BK1: ENERO | BL1: FEBRERO | BM1: MARZO | BN1: ABRIL | BO1: MAYO | BP1: JUNIO | BQ1: JULIO | BR1: AGOSTO | BS1: SEPTIEMBRE | BT1: OCTUBRE | BU1: NOVIEMBRE | BV1: DICIEMBRE | BW1: ENERO | BX1: FEBRERO | BY1: MARZO | BZ1: ABRIL | CA1: MAYO | CB1: JUNIO | CD1: DEUDA | CE1: % | CI1: GASTOS | CJ1: VALOR
A2: SEGURIDAD SOCIAL | B2: 1000000 | C2: 1113000 | D2: 1588000 | E2: 1732000 | F2: 1422000 | G2: 1000000 | H2: 1000000 | I2: 1500000 | J2: 1800000 | K2: 3100000 | L2: 2708500 | M2: 2800000 | N2: 2553300 | O2: 3033000 | P2: 3500000 | Q2: 2500000 | R2: 3740000 | S2: 2500000 | T2: 3050000 | U2: 4890000 | V2: 4000000 | W2: 3800000 | X2: 4000000 | Y2: 3750000 | Z2: 4500000 | AA2: 6000000 | AB2: 4700000 | AC2: 5000000 | AD2: 5000000 | AE2: 4000000 | AF2: 5500000 | AG2: 3800000 | AH2: 4500000 | AI2: 5000000 | AJ2: 4500000 | AK2: 7000000 | AL2: 10000000 | AM2: 6000000 | AN2: 6800000 | AO2: 7000000 | AP2: 8000000 | AQ2: 5500000 | AR2: 7000000 | AS2: 7000000 | AT2: 7000000 | AU2: 7000000 | AV2: 10000000 | AW2: 8000000 | AX2: 10000000 | AY2: 5000000 | AZ2: 7000000 | BA2: 6000000 | BB2: 6470000 | BC2: 5500000 | BD2: 4700000 | BE2: 8000000 | BF2: 6200000 | BG2: 6000000 | BH2: 7000000 | BI2: 5000000 | BJ2: 7000000 | BK2: 5000000 | BL2: 7000000 | BM2: 6000000 | BN2: 5700000 | BO2: 6500000 | BP2: 5000000 | BQ2: 7500000 | BR2: 6000000 | BS2: 9000000 | BT2: 4500000 | BU2: 4500000 | BV2: 6000000 | BW2: 5600000 | BX2: 4500000 | BY2: 7000000 | BZ2: 6000000 | CA2: 7000000 | CI2: Arriendo | CJ2: 700000
A3: FECOP | B3: 3500000 | BK3: 0 | BL3: 0 | BM3: 3700000 | BN3: 3996000 | BO3: 3848000 | BP3: 3878000 | BQ3: 3992000 | BR3: 4188000 | BS3: 4133000 | BT3: 4506000 | BU3: 4391000 | BV3: 4314000
A4: Megamudanzas CAMIONES | B4: 0 | C4: 0 | D4: 0 | E4: 0 | F4: 0 | G4: 0 | H4: 0 | I4: 0 | J4: 0 | K4: 0 | L4: 0 | M4: 2550000 | N4: 2500000 | O4: 2500000 | P4: 650000 | Q4: 1500000 | R4: 700000 | S4: 1150000 | T4: 2000000 | U4: 2250000 | V4: 2500000 | W4: 2500000 | X4: 2500000 | Y4: 2500000 | Z4: 2500000 | AA4: 2000000 | AB4: 2000000 | AC4: 2000000 | AD4: 2000000 | AE4: 2000000 | AF4: 2500000 | AG4: 2500000 | AH4: 2500000 | AI4: 2500000 | AJ4: 2200000 | AK4: 2500000 | AL4: 2500000 | AM4: 2500000 | AN4: 2000000 | AO4: 2000000 | AP4: 2000000 | AQ4: 2000000 | AR4: 2000000 | AS4: 2000000 | AT4: 2000000 | AU4: 2000000 | AV4: 2500000 | AW4: 2500000 | AX4: 2500000 | AY4: 2500000 | AZ4: 3000000 | BA4: 3000000 | BB4: 2500000 | BC4: 2000000 | BD4: 1100000 | BE4: 1400000 | BF4: 1300000 | BG4: 1500000 | BH4: 1500000 | BI4: 1500000 | BJ4: 1500000 | BK4: 1500000 | BL4: 2000000 | BM4: 1000000 | BN4: 2000000 | BO4: 2000000 | BP4: 2000000 | BQ4: 2000000 | BR4: 1750000 | BS4: 2000000 | BT4: 2000000 | BU4: 2000000 | CI4: Mercado | CJ4: 500000
A5: Mega-Transportes JUAMVI | B5: 0 | AV5: 0 | AW5: 0 | AX5: 0 | AY5: 0 | AZ5: 0 | BA5: 0 | BB5: 0 | BC5: 0 | BD5: 1400000 | BE5: 1500000 | BF5: 1600000 | BG5: 1700000 | BH5: 2000000 | BI5: 3000000 | BJ5: 2500000 | BK5: 1500000 | BL5: 0 | BM5: 3000000 | BN5: 2500000 | BO5: 2000000 | BP5: 0 | BQ5: 1500000 | BR5: 2000000 | BS5: 1300000 | BT5: 2000000 | BU5: 1400000
A6: Halcon | AN6: 685000 | AO6: 0 | AP6: 0 | AQ6: 0 | AR6: 0 | AS6: 0 | AT6: 0 | AU6: 0 | BB6: 2000000
A7: Cuenta Facil | BL7: 2470000 | BM7: 2470000 | BN7: 2470000 | BO7: 2470000 | BP7: 2470000 | BQ7: 2470000 | BR7: 2470000 | BS7: 0 | BT7: 0 | BU7: 0 | BV7: 28000000
A8: Llamadas | B8: 800000 | C8: 1000000 | D8: 1000000 | E8: 1000000 | F8: 1000000 | G8: 500000 | H8: 500000 | I8: 500000 | J8: 500000 | K8: 500000 | L8: 500000 | M8: 500000 | N8: 500000 | O8: 500000 | P8: 500000 | Q8: 500000 | R8: 500000 | S8: 500000 | T8: 500000 | U8: 500000 | V8: 500000 | W8: 500000 | X8: 500000 | Y8: 500000 | Z8: 500000 | AA8: 1000000 | AB8: 1000000 | AC8: 1000000 | AD8: 1000000 | AE8: 1000000 | AF8: 1000000 | AG8: 1000000 | AH8: 1000000 | AI8: 1000000 | AJ8: 1000000 | AK8: 1000000 | AL8: 1000000 | AM8: 1000000 | AN8: 1000000 | AO8: 1000000 | AP8: 1000000 | AQ8: 1000000 | AR8: 1000000 | AS8: 1000000 | AT8: 1000000 | AU8: 1000000 | AV8: 1000000 | AW8: 1000000 | AX8: 1000000 | AY8: 2000000 | AZ8: 2000000 | BA8: 2000000 | BB8: 2000000 | BC8: 2000000 | BD8: 2000000 | BE8: 2000000 | BF8: 2000000 | BG8: 2000000 | BH8: 2000000 | BI8: 2000000 | BJ8: 2000000 | BK8: 2000000 | BL8: 2000000 | BM8: 2000000 | BN8: 2000000 | BO8: 2000000 | BP8: 2000000 | BQ8: 2000000 | BR8: 2000000 | BS8: 2000000 | BT8: 2000000 | BU8: 2000000 | BV8: 2000000 | CI8: Diezmo | CJ8: 600000
A9: Internet | B9: 500000 | C9: -500000 | D9: 525000 | E9: 160000 | F9: 270000 | G9: -200000 | H9: -72000 | I9: 136000 | J9: 422000 | K9: 400000 | L9: 283000 | M9: -382000 | N9: 398000 | O9: -300000 | P9: 445000 | Q9: 320000 | R9: 333000 | S9: 692000 | T9: 700000 | U9: 600000 | V9: 196000 | W9: 180000 | X9: 652000 | Y9: 800000 | Z9: 350000 | AA9: 553000 | AB9: 280000 | AC9: 570000 | AD9: 226000 | AE9: 330000 | AF9: 502000 | AG9: 300000 | AH9: 406000 | AI9: 350000 | AJ9: 929000 | AK9: 580000 | AL9: 800000 | AM9: 0 | AN9: 62000 | AO9: 210000 | AP9: -487000 | AQ9: 0 | AR9: 0 | AS9: 0 | AT9: 0 | AU9: 0 | AV9: 0 | AW9: 0 | AY9: 798000 | AZ9: 788000 | BA9: 811000 | BB9: 811000 | BC9: 767000 | BD9: 691000 | BE9: 490000 | BF9: 478000 | BG9: 572000 | BH9: 389000 | BI9: 509000 | BJ9: 389000 | BK9: 0 | BL9: 0 | CI9: Gasolina | CJ9: 400000
A10: Mave integral -MARIANA | B10: 125000 | C10: 500000 | D10: 500000 | E10: 125000 | F10: 125000 | G10: 125000 | H10: 250000 | I10: 250000 | J10: 250000 | K10: 250000 | L10: 250000 | M10: 200000 | N10: 200000 | O10: 200000 | P10: 250000 | Q10: 250000 | R10: 250000 | S10: 250000 | T10: 330000 | U10: 330000 | V10: 330000 | W10: 330000 | X10: 330000 | Y10: 330000 | Z10: 330000 | AA10: 330000 | AB10: 330000 | AC10: 330000 | AD10: 330000 | AE10: 330000 | AF10: 330000 | AG10: 330000 | AH10: 330000 | AI10: 330000 | AJ10: 330000 | AK10: 330000 | AL10: 330000 | AM10: 330000 | AN10: 330000 | AO10: 330000 | AP10: 330000 | AQ10: 330000 | AR10: 330000 | AS10: 330000 | AT10: 330000 | AU10: 330000 | AV10: 330000 | AW10: 330000 | AX10: 330000 | AY10: 330000 | AZ10: 330000 | BA10: 330000 | BB10: 330000 | BC10: 330000 | BD10: 330000 | BE10: 330000 | BF10: 330000 | BG10: 330000 | BH10: 330000 | BI10: 330000 | BJ10: 330000 | BK10: 380000 | BL10: 380000 | BM10: 380000 | BN10: 380000 | BO10: 380000 | BP10: 380000 | BQ10: 380000 | BR10: 380000 | BS10: 380000 | BT10: 380000 | BU10: 380000 | BV10: 380000 | CI10: Parqueadero | CJ10: 200000
A11: Mave integral - ANDERSON | B11: 125000 | C11: 500000 | D11: 500000 | E11: 125000 | F11: 125000 | G11: 125000 | H11: 250000 | I11: 250000 | J11: 250000 | K11: 250000 | L11: 250000 | M11: 250000 | N11: 250000 | O11: 250000 | P11: 250000 | Q11: 250000 | R11: 250000 | S11: 250000 | T11: 570000 | U11: 330000 | V11: 330000 | W11: 330000 | X11: 280000 | Y11: 280000 | Z11: 280000 | AA11: 280000 | AB11: 280000 | AC11: 280000 | AD11: 280000 | AE11: 280000 | AF11: 280000 | AG11: 330000 | AH11: 330000 | AI11: 330000 | AJ11: 330000 | AK11: 330000 | AL11: 330000 | AM11: 330000 | AN11: 330000 | AO11: 330000 | AP11: 330000 | AQ11: 330000 | AR11: 330000 | AS11: 330000 | AT11: 330000 | AU11: 330000 | AV11: 330000 | AW11: 330000 | AX11: 330000 | AY11: 330000 | AZ11: 330000 | BA11: 330000 | BB11: 330000 | BC11: 330000 | BD11: 330000 | BE11: 330000 | BF11: 330000 | BG11: 330000 | BH11: 330000 | BI11: 330000 | BJ11: 330000 | BK11: 380000 | BL11: 380000 | BM11: 380000 | BN11: 380000 | CI11: Cadena | CJ11: 120000 | CQ11: pago el 5-marzo-20 | CR11: 860000
A12: MURO INTEGRAL | B12: 200000 | C12: 0 | D12: 0 | E12: 0 | F12: 0 | G12: 0 | H12: 0 | I12: 0 | J12: 0 | K12: 0 | L12: 0 | M12: 0 | N12: 300000 | O12: 200000 | P12: 200000 | Q12: 200000 | R12: 280000 | S12: 280000 | T12: 280000 | U12: 280000 | V12: 280000 | W12: 280000 | X12: 280000 | Y12: 280000 | Z12: 280000 | AA12: 280000 | AB12: 280000 | AC12: 280000 | AD12: 280000 | AE12: 280000 | AF12: 280000 | AG12: 280000 | AH12: 280000 | AI12: 280000 | AJ12: 280000 | AK12: 280000 | AL12: 280000 | AM12: 280000 | AN12: 280000 | AO12: 280000 | AP12: 280000 | AY12: 280000 | AZ12: 280000 | BA12: 280000 | BB12: 280000 | BC12: 280000 | BD12: 280000 | BE12: 280000 | BF12: 280000 | BG12: 280000 | BH12: 280000 | BI12: 280000 | BJ12: 280000 | BK12: 280000 | BL12: 280000 | BM12: 280000 | BN12: 280000 | BO12: 0 | BP12: 0 | BQ12: 830000 | CI12: Geral | CJ12: 500000
A13: FAGA - INTEGRAL | B13: 180000 | BH13: 0 | BI13: 0 | BJ13: 0 | BK13: 0 | BL13: 0 | BM13: 300000 | BN13: 180000 | BO13: 180000 | BP13: 180000 | BQ13: 180000 | BR13: 180000 | BS13: 180000 | BT13: 180000 | BU13: 180000
A14: INTERESES PRESTAMOS | AR14: 0 | AS14: 0 | AT14: 0 | AU14: 0 | AV14: 0 | AW14: 0 | AX14: 0 | AY14: 2419000 | AZ14: 3118706.2 | BA14: 3337892.3 | BB14: 2789696 | BC14: 2000000 | BD14: 2000000 | BE14: 2000000 | BF14: 2000000 | BG14: 2000000 | BH14: 2000000 | BI14: 2000000 | BJ14: 2789696 | BK14: 2200000 | BL14: 2200000 | BM14: 2200000 | BN14: 2200000 | BO14: 2200000 | BP14: 3200000 | BQ14: 3200000
A15: Congreso | B15: 500000 | C15: 500000 | D15: 500000 | E15: 500000 | F15: 500000 | G15: 500000 | H15: 500000 | I15: 500000 | J15: 500000 | K15: 500000 | L15: 500000 | M15: 500000 | N15: 500000 | O15: 500000 | P15: 500000 | Q15: 500000 | R15: 500000 | S15: 500000 | T15: 500000 | U15: 500000 | V15: 500000 | W15: 500000 | X15: 500000 | Y15: 500000 | Z15: 500000 | AA15: 500000 | AB15: 500000 | AC15: 500000 | AD15: 500000 | AE15: 500000 | AF15: 500000 | AG15: 500000 | AH15: 500000 | AI15: 500000 | AJ15: 500000 | AK15: 500000 | AL15: 500000 | AM15: 600000 | AN15: 600000 | AO15: 600000 | AP15: 600000 | AQ15: 600000 | AR15: 600000 | AS15: 600000 | AT15: 600000 | AU15: 600000 | AV15: 600000 | AW15: 600000 | AX15: 600000 | AY15: 600000 | AZ15: 750000 | BA15: 750000 | BB15: 750000 | BC15: 750000 | BD15: 750000 | BE15: 750000 | BF15: 750000 | BG15: 750000 | BH15: 750000 | BI15: 750000 | BJ15: 750000 | BK15: 750000 | BL15: 750000 | BM15: 750000 | BN15: 750000 | BO15: 750000 | BP15: 750000 | BQ15: 750000 | BR15: 750000 | BS15: 750000 | BT15: 750000 | BU15: 750000 | BV15: 750000 | CI15: transporte niños | CJ15: 150000 | CQ15: pago el 5-marzo-20 | CR15: 860000
A16: Concejo rolo | B16: 500000 | C16: 500000 | D16: 500000 | E16: 500000 | F16: 500000 | G16: 500000 | H16: 500000 | I16: 500000 | J16: 500000 | K16: 500000 | L16: 500000 | M16: 500000 | N16: 500000 | O16: 500000 | P16: 500000 | Q16: 500000 | R16: 500000 | S16: 500000 | T16: 500000 | U16: 500000 | V16: 500000 | W16: 500000 | X16: 500000 | Y16: 500000 | Z16: 500000 | AD16: 500000 | AE16: 500000 | AF16: 500000 | CI16: Comida fuera | CJ16: 500000
A17: Servidor Web | B17: 200000 | C17: 200000 | D17: 200000 | E17: 200000 | F17: 200000 | G17: 200000 | H17: 200000 | I17: 200000 | J17: 200000 | K17: 200000 | L17: 200000 | M17: 200000 | N17: 200000 | O17: 150000 | P17: 200000 | Q17: 200000 | R17: 200000 | S17: 200000 | T17: 200000 | U17: 200000 | V17: 200000 | W17: 200000 | X17: 200000 | Y17: 200000 | Z17: 200000 | AA17: 200000 | AB17: 200000 | AC17: 200000 | AD17: 200000 | AE17: 0 | AF17: 0 | AG17: 0 | AH17: 0 | AI17: 0 | AJ17: 0 | AK17: 0 | AL17: 0 | AM17: 0 | AN17: 0 | AO17: 0 | AP17: 0 | AQ17: 0 | AR17: 0 | AS17: 0 | AT17: 0 | AU17: 0 | AV17: 0 | AW17: 0 | AX17: 0
A18: Programa Org | B18: 300000 | C18: 300000 | D18: 300000 | E18: 300000 | F18: 300000 | G18: 0 | H18: 0 | I18: 0 | J18: 0 | K18: 0 | L18: 250000 | M18: 250000 | N18: 250000 | O18: 250000 | P18: 250000 | Q18: 250000 | R18: 250000 | S18: 250000 | T18: 250000 | U18: 250000 | V18: 250000 | W18: 250000 | X18: 250000 | Y18: 250000 | Z18: 250000 | AA18: 250000 | AB18: 250000 | AC18: 250000 | AD18: 250000 | AE18: 250000 | AF18: 250000 | AG18: 250000 | AH18: 250000 | AI18: 250000 | AJ18: 250000 | AK18: 250000 | AL18: 250000 | AM18: 250000 | AN18: 250000 | AO18: 250000 | AP18: 250000 | AQ18: 250000 | AR18: 250000 | AS18: 250000 | AT18: 250000 | AU18: 250000 | AV18: 250000 | AW18: 250000 | AX18: 250000 | AY18: 250000 | AZ18: 250000 | BA18: 250000 | BB18: 250000 | BC18: 250000 | BD18: 250000 | BE18: 250000 | BF18: 250000 | BG18: 250000 | BH18: 250000 | BI18: 250000 | BJ18: 250000 | BK18: 250000 | BL18: 250000 | BM18: 250000 | BN18: 250000 | BO18: 250000 | BP18: 250000 | BQ18: 250000 | BR18: 250000 | BS18: 250000 | BT18: 250000 | BU18: 250000 | BV18: 250000
A19: JOYERIA 18K | B19: 120000 | C19: 500000 | D19: 500000 | E19: 75000 | F19: 75000 | G19: 100000 | H19: 100000 | I19: 100000 | J19: 100000 | K19: 100000 | L19: 100000 | M19: 100000 | N19: 100000 | O19: 75000 | P19: 75000 | Q19: 75000 | R19: 75000 | S19: 75000 | T19: 75000 | U19: 75000 | V19: 100000 | W19: 75000 | X19: 75000 | Y19: 75000 | Z19: 75000 | AA19: 75000 | AB19: 75000 | AG19: 0 | AH19: 0 | AI19: 0 | AJ19: 0 | AK19: 0 | AL19: 0 | AM19: 0 | AN19: 0 | AO19: 0
A20: CONTRATO CONCEJO | B20: 980000 | C20: 980000 | D20: 980000 | E20: 980000 | F20: 980000 | G20: 1970000 | H20: 2200000 | I20: 0 | J20: 0 | K20: 0 | L20: 0 | M20: 2000000 | N20: 1900000 | O20: 1800000 | P20: 1800000 | Q20: 2000000 | R20: 2000000 | S20: 2000000 | T20: 2000000 | U20: 2000000 | V20: 2000000 | W20: 2000000 | X20: 2000000 | Y20: 2000000 | Z20: 500000 | AA20: 3280000 | AB20: 2982000 | AC20: 3280000 | AD20: 3280000 | AE20: 3280000 | AF20: 3362000 | AG20: 3100000 | AH20: 3837000 | AI20: 4320000 | AJ20: 4300000 | AK20: 3918000 | AL20: 3918000 | AM20: 4300000 | AN20: 4200000 | AO20: 3967000 | AP20: 3967000 | AQ20: 3800000 | AR20: 4300000 | AS20: 3000000 | AT20: 3970000 | AU20: 3970000 | AV20: 3970000 | AW20: 4300000 | AX20: 3000000 | AY20: 2500000 | AZ20: 4300000 | BA20: 3203000 | BB20: 4000000 | BC20: 3760000 | BD20: 3760000 | BE20: 3760000 | BF20: 3946000 | BG20: 4119000 | BH20: 4500000 | BI20: 4200000 | BJ20: 3946000 | BK20: 4500000 | BL20: 4500000 | BM20: 4500000 | BN20: 4500000 | BO20: 4500000 | BP20: 4500000 | BQ20: 4500000 | BR20: 4500000 | BS20: 4500000 | BT20: 4500000 | BU20: 4500000 | BV20: 4500000
A21: Intereses Lucy 2 | B21: =CD21*CE21 -> 110250 | C21: 0 | D21: 35000 | E21: 35000 | F21: 35000 | G21: 35000 | H21: 35000 | I21: 256000 | J21: 291000 | K21: 300000 | L21: 300000 | M21: 300000 | N21: 300000 | O21: 300000 | P21: 300000 | Q21: 300000 | R21: 300000 | S21: 300000 | T21: 300000 | U21: 300000 | V21: 300000 | W21: 300000 | X21: 250000 | Y21: 250000 | Z21: 250000 | AA21: 250000 | AB21: 210000 | AC21: 200000 | AD21: 50000 | AE21: 250000 | AF21: 0 | AG21: 250000 | AH21: 250000 | AI21: 200000 | AJ21: 200000 | AK21: 90000 | AL21: 200000 | AM21: 0 | AN21: 200000 | AO21: 200000 | AP21: 200000 | AQ21: 200000 | AR21: 100000 | AS21: 200000 | AT21: 200000 | AU21: 0 | AV21: 200000 | AW21: 200000 | AX21: 0 | CD21: 3150000 | CE21: 0.035 | CF21: 30 | CJ21: =SUM(CJ2:CJ20) -> 3670000
A22: HECTOR MEDINA AVIOMAR | B22: =CD22*CE22 -> 280000 | C22: 0 | D22: 0 | E22: 0 | F22: 0 | G22: 0 | H22: 0 | I22: 0 | J22: 0 | K22: 0 | L22: 35000 | M22: 105000 | N22: 105000 | O22: 105000 | P22: 280000 | Q22: 0 | R22: 1000000 | S22: 1000000 | T22: 1488000 | U22: 0 | V22: 500000 | W22: 0 | X22: 1000000 | Y22: 2000000 | Z22: 1000000 | AA22: 0 | AB22: 100000 | AC22: 600000 | AD22: 0 | AE22: 900000 | AF22: 0 | AG22: 1000000 | AH22: 0 | AI22: 0 | AJ22: 1000000 | AK22: 2000000 | AL22: 0 | AM22: 0 | AN22: 1000000 | AO22: 250000 | AT22: 1000000 | CD22: 8000000 | CE22: 0.035 | CF22: 2
A23: TOÑO- MIGUEL ANTONIO | I23: 0 | J23: 0 | K23: 0 | L23: 0 | M23: 0 | N23: 0 | O23: 0 | P23: 0 | Q23: 0 | R23: 120000 | S23: 120000 | T23: 100000 | U23: 50000 | V23: 0 | W23: 300000 | X23: 0 | Y23: 200000 | Z23: 100000 | AA23: 200000 | AB23: 150000 | AC23: 200000 | AD23: 0 | AE23: 0 | AF23: 100000 | AG23: 0 | AH23: 100000 | AI23: 100000 | AJ23: 100000 | AK23: 100000 | AL23: 100000 | AM23: 100000 | AN23: 100000 | AO23: 0 | AP23: 100000 | AQ23: 100000 | AR23: 100000 | AS23: 100000 | AT23: 100000 | AU23: 100000 | AV23: 100000 | AW23: 100000 | AX23: 100000 | CD23: 2000000 | CE23: 0.035 | CF23: 1
A24: Veronica Peña - Arroyave | B24: =CD24*CE24 -> 45000 | C24: 0 | D24: 0 | E24: 53000 | F24: 53000 | G24: 53000 | H24: 53000 | I24: 53000 | J24: 53000 | K24: 53000 | L24: 53000 | M24: 553000 | N24: 45000 | O24: 45000 | P24: 45000 | Q24: 45000 | R24: 45000 | S24: 45000 | T24: 45000 | U24: 45000 | V24: 45000 | W24: 45000 | X24: 45000 | Y24: 45000 | Z24: 45000 | AA24: 45000 | AB24: 45000 | AC24: 45000 | AD24: 45000 | AE24: 45000 | AF24: 45000 | AG24: 45000 | AH24: 45000 | AI24: 45000 | AJ24: 45000 | AK24: 45000 | AL24: 45000 | AM24: 45000 | AN24: 45000 | AO24: 45000 | AP24: 45000 | AQ24: 45000 | AR24: 45000 | AS24: 45000 | AT24: 45000 | AU24: 45000 | AV24: 45000 | AW24: 45000 | AX24: 45000 | CD24: 3000000 | CE24: 0.015 | CF24: 5
A25: Prestamos Halcon | AO25: 1000000 | AP25: 1000000 | AQ25: 1000000 | AR25: 500000 | AS25: 500000 | AT25: 500000 | CD25: 14700000 | CE25: 0.035 | CF25: 5
A26: Jessica ramirez - diana | U26: 0 | V26: 0 | W26: 0 | X26: 0 | Y26: 0 | Z26: 0 | AA26: 0 | AB26: 0 | AC26: 0 | AD26: 1200000 | AE26: 1140000 | AF26: 1100000 | AG26: 1100000 | AH26: 500000 | AI26: 498000 | AJ26: 0 | AK26: 0 | AL26: 0 | AM26: 0 | AN26: 0 | AO26: 0
A27: Fabionelson Ocoro | Z27: 0 | AA27: 50000 | AB27: 50000 | AC27: 1120000 | AD27: 0 | AP27: 500000 | AR27: 200000 | CD27: 1500000
A28: Intereses Humberto Pineda | B28: =CD28*CE28 -> 70000 | C28: 0 | D28: 0 | E28: 0 | F28: 0 | G28: 0 | H28: 0 | I28: 0 | J28: 0 | K28: 70000 | L28: 70000 | M28: 0 | N28: 140000 | O28: 70000 | P28: 70000 | Q28: 0 | R28: 70000 | S28: 70000 | T28: 70000 | AD28: 210000 | AI28: 1000000 | AL28: 1500000 | AM28: 0 | CD28: 2000000 | CE28: 0.035
A29: JHON JAIRO MUÑOZ | C29: 0 | D29: 0 | E29: 0 | F29: 0 | G29: 0 | H29: 0 | I29: 0 | J29: 0 | K29: 0 | L29: 0 | M29: 0 | N29: 500000 | CD29: 1830000 | CE29: 0.035
A30: Intereses Einer Mejia | B30: =CD30*CE30 -> 45500 | C30: 0 | D30: 0 | E30: 0 | F30: 0 | G30: 0 | H30: 0 | I30: 0 | J30: 0 | K30: 0 | L30: 0 | M30: 12000 | N30: 200000 | O30: 100000 | P30: 100000 | Q30: 0 | R30: 25000 | S30: 0 | T30: 117000 | CD30: 1300000 | CE30: 0.035 | CF30: 10
A31: Intereses Edgar Garcia | B31: =CD31*CE31 -> 73500 | C31: 0 | D31: 100000 | E31: 0 | F31: 45000 | K31: 100000 | L31: 400000 | CD31: 2100000 | CE31: 0.035 | CF31: 30
A32: intereses estefania bareiro | B32: =CD32*CE32 -> 42000 | C32: 0 | D32: 60000 | E32: 120000 | F32: 120000 | G32: 120000 | H32: 120000 | I32: 120000 | J32: 120000 | K32: 600000 | T32: 250000 | Z32: 300000 | AH32: 300000 | AI32: 300000 | CD32: 1200000 | CE32: 0.035 | CF32: 28
A33: intereses estefania bareiro | B33: =CD33*CE33 -> 30450 | C33: 0 | D33: 0 | E33: 0 | F33: 0 | G33: 0 | H33: 0 | I33: 0 | J33: 0 | K33: 400000 | CD33: 870000 | CE33: 0.035 | CF33: 5
A34: Intereses Viviana Gil | B34: =CD34*CE34 -> 19600 | C34: 0 | D34: 53000 | E34: 0 | F34: 0 | G34: 0 | H34: 0 | I34: 0 | J34: 0 | K34: 0 | L34: 0 | M34: 0 | N34: 0 | O34: 0 | P34: 0 | Q34: 0 | R34: 0 | S34: 0 | T34: 0 | U34: 0 | V34: 0 | W34: 0 | X34: 0 | Y34: 0 | Z34: 0 | AA34: 0 | AB34: 0 | AC34: 0 | AD34: 0 | AE34: 0 | AF34: 0 | AG34: 0 | AH34: 0 | AI34: 0 | AJ34: 0 | AK34: 0 | AL34: 0 | CD34: 560000 | CE34: 0.035 | CF34: 5
A35: Intereses Martin Chavez | B35: =CD35*CE35 -> 35000 | C35: 35000 | D35: 0 | E35: 0 | F35: 0 | G35: 0 | H35: 0 | I35: 0 | J35: 0 | K35: 0 | L35: 0 | M35: 0 | N35: 0 | O35: 0 | P35: 0 | Q35: 0 | R35: 0 | S35: 0 | T35: 0 | U35: 0 | V35: 0 | W35: 0 | X35: 0 | Y35: 0 | Z35: 0 | AA35: 0 | AB35: 0 | AC35: 0 | AD35: 0 | AE35: 0 | AF35: 0 | AG35: 0 | AH35: 0 | AI35: 400000 | AJ35: 0 | AK35: 400000 | AL35: 300000 | CD35: 1000000 | CE35: 0.035 | CF35: 10
A36: Diana Molina | B36: =CD36*CE36 -> 0 | C36: 0 | D36: 0 | E36: 0 | F36: 0 | G36: 0 | H36: 0 | I36: 0 | J36: 0 | K36: 0 | L36: 0 | M36: 0 | N36: 0 | O36: 0 | P36: 0 | Q36: 0 | R36: 0 | S36: 0 | T36: 0 | U36: 0 | V36: 0 | W36: 0 | X36: 0 | Y36: 0 | Z36: 0 | AA36: 0 | AB36: 0 | AC36: 0 | AD36: 0 | AE36: 0 | AF36: 0 | AG36: 0 | AH36: 0 | AI36: 0 | AJ36: 0 | AK36: 0 | AL36: 0 | CD36: 1700000 | CE36: 0 | CF36: 5
A37: manzano | B37: =CD37*CE37 -> 0 | C37: 0 | D37: 0 | E37: 0 | F37: 0 | G37: 0 | H37: 0 | I37: 0 | J37: 0 | K37: 0 | L37: 0 | M37: 0 | N37: 0 | O37: 0 | P37: 0 | Q37: 0 | R37: 0 | S37: 0 | T37: 0 | U37: 0 | V37: 0 | W37: 0 | X37: 0 | Y37: 0 | Z37: 0 | AA37: 0 | AB37: 0 | AC37: 0 | AD37: 0 | AE37: 0 | AF37: 0 | AG37: 0 | AH37: 0 | AI37: 0 | AJ37: 0 | AK37: 0 | AL37: 0 | CD37: 500000
A38: intereses johana barona 1 | B38: =CD38*CE38 -> 4900 | C38: 0 | D38: 21000 | E38: 21000 | F38: 21000 | G38: 0 | H38: 0 | I38: 0 | J38: 0 | K38: 600000 | X38: 0 | Y38: 0 | Z38: 0 | AA38: 0 | AB38: 0 | AC38: 0 | AD38: 0 | AE38: 0 | AF38: 0 | AG38: 0 | AH38: 0 | AI38: 0 | AJ38: 0 | AK38: 0 | AL38: 0 | AM38: 0 | AN38: 0 | AO38: 0 | AP38: 0 | AQ38: 0 | AR38: 0 | AS38: 0 | AT38: 0 | AU38: 0 | AV38: 0 | AW38: 0 | AX38: 0 | AY38: 0 | CD38: 140000 | CE38: 0.035 | CF38: 25
A39: intereses johana barona 2 | B39: =CD39*CE39 -> 70000 | C39: 0 | D39: 0 | E39: 0 | F39: 0 | G39: 0 | H39: 0 | I39: 0 | J39: 0 | K39: 0 | L39: 0 | M39: 0 | N39: 0 | O39: 0 | P39: 0 | Q39: 0 | R39: 0 | S39: 0 | T39: 0 | U39: 0 | V39: 0 | W39: 0 | X39: 0 | Y39: 0 | Z39: 0 | AA39: 0 | AB39: 2000000 | AC39: 0 | AD39: 0 | AE39: 0 | AF39: 0 | AG39: 0 | AH39: 0 | AI39: 0 | AJ39: 0 | AK39: 0 | AL39: 0 | AM39: 0 | AN39: 0 | AO39: 0 | AP39: 0 | AQ39: 0 | AR39: 0 | AS39: 0 | AT39: 0 | AU39: 0 | AV39: 0 | AW39: 0 | AX39: 0 | AY39: 0 | CD39: 2000000 | CE39: 0.035 | CF39: 5
A40: efecty | B40: 250000 | C40: 265000 | D40: 520000 | E40: 863000 | F40: 1831000 | G40: 1842000 | H40: 1514000 | I40: 1637000 | J40: 1414000 | K40: 1640000 | L40: 1504000 | M40: 1633320 | N40: 1303456 | O40: 1207000 | P40: 1197000 | Q40: 1474000 | R40: 1218716 | S40: 1265758 | T40: 299000 | U40: 0 | V40: 0 | W40: 0 | X40: 0 | Y40: 0 | Z40: 0 | AA40: 0 | AB40: 0 | AC40: 0 | AD40: 0 | AE40: 0 | AF40: 0 | AG40: 0 | AH40: 0 | AI40: 0 | AJ40: 0 | AK40: 0 | AL40: 0 | AM40: 0 | AN40: 0 | AO40: 0 | AP40: 0 | AQ40: 0 | AR40: 0 | AS40: 0 | AT40: 0 | AU40: 0 | AV40: 0 | AW40: 0 | AX40: 0 | AY40: 0 | CD40: 0
...

Sheet GASTOS
A1: No. | D1: FECHA | E1: ENTRADAS | F1: SALIDA | G1: PRESTAMOS | H1: INVERSION | I1: TIPO | J1: DESCRIPCION
A2: 1 | B2: =YEAR(D2) -> 2020 | C2: =MONTH(D2) -> 1 | D2: 43849 | F2: 100000 | I2: GASOLINA | J2: tanqueo
A3: 2 | B3: =YEAR(D3) -> 2020 | C3: =MONTH(D3) -> 1 | D3: 43852 | F3: 800000 | I3: OTROS | J3: Compra de portatil Dell
A4: 3 | B4: =YEAR(D4) -> 2020 | C4: =MONTH(D4) -> 1 | D4: 43852 | F4: 150000 | I4: OTROS | J4: giro c
A5: 4 | B5: =YEAR(D5) -> 2020 | C5: =MONTH(D5) -> 1 | D5: 43852 | F5: 4000 | I5: COMIDA | J5: desayuno
A6: 5 | B6: =YEAR(D6) -> 2020 | C6: =MONTH(D6) -> 1 | D6: 43852 | F6: 12000 | I6: OTROS | J6: peluquiada
A7: 6 | B7: =YEAR(D7) -> 2020 | C7: =MONTH(D7) -> 1 | D7: 43853 | F7: 2500 | I7: COMIDA | J7: desayuno
A8: 7 | B8: =YEAR(D8) -> 2020 | C8: =MONTH(D8) -> 1 | D8: 43853 | F8: 10000 | I8: COMIDA | J8: almuerzo
A9: 8 | B9: =YEAR(D9) -> 2020 | C9: =MONTH(D9) -> 1 | D9: 43853 | F9: 53000 | G9: 0 | I9: PRESTAMO | J9: giro a viviana gil - prestamos
A10: 9 | B10: =YEAR(D10) -> 2020 | C10: =MONTH(D10) -> 1 | D10: 43853 | F10: 100000 | I10: TRABAJOS | J10: mandar hacer libros iglesia
A11: 10 | B11: =YEAR(D11) -> 2020 | C11: =MONTH(D11) -> 1 | D11: 43853 | F11: 5200 | I11: PARQUEADERO | J11: parqueadero éxito
A12: 11 | B12: =YEAR(D12) -> 2020 | C12: =MONTH(D12) -> 1 | D12: 43853 | F12: 2500 | I12: COMIDA | J12: presa de pollo cena
A13: 12 | B13: =YEAR(D13) -> 2020 | C13: =MONTH(D13) -> 1 | D13: 43854 | F13: 3000 | I13: COMIDA | J13: desayuno
A14: 13 | B14: =YEAR(D14) -> 2020 | C14: =MONTH(D14) -> 1 | D14: 43854 | F14: 50000 | I14: SALIDAS | J14: cumpleaños de Abraham Cortes
A15: 14 | B15: =YEAR(D15) -> 2020 | C15: =MONTH(D15) -> 1 | D15: 43854 | F15: 5000 | I15: COMIDA | J15: almuerzo
A16: 15 | B16: =YEAR(D16) -> 2020 | C16: =MONTH(D16) -> 1 | D16: 43856 | F16: 70000 | I16: SALIDAS | J16: salida cajita feliz
A17: 16 | B17: =YEAR(D17) -> 2020 | C17: =MONTH(D17) -> 1 | D17: 43856 | F17: 10000 | I17: COMIDA | J17: cena
A18: 17 | B18: =YEAR(D18) -> 2020 | C18: =MONTH(D18) -> 1 | D18: 43856 | F18: 14000 | I18: OTROS | J18: boonyurg y regeneris
A19: 18 | B19: =YEAR(D19) -> 2020 | C19: =MONTH(D19) -> 1 | D19: 43857 | F19: 5000 | I19: COMIDA | J19: desayuno
A20: 19 | B20: =YEAR(D20) -> 2020 | C20: =MONTH(D20) -> 1 | D20: 43857 | F20: 10000 | I20: COMIDA | J20: almuerzo
A21: 20 | B21: =YEAR(D21) -> 2020 | C21: =MONTH(D21) -> 1 | D21: 43857 | F21: 2000 | I21: COMIDA | J21: pan cena
... A26: 25 | B26: =YEAR(D26) -> 2020 | C26: =MONTH(D26) -> 1 | D26: 43860 | F26: 10000 | I26: COMIDA | J26: desayuno
A27: 26 | B27: =YEAR(D27) -> 2020 | C27: =MONTH(D27) -> 1 | D27: 43860 | E27: 225000 | I27: ENTRADA | J27: ENVIO DE SMS
A28: 27 | B28: =YEAR(D28) -> 2020 | C28: =MONTH(D28) -> 1 | D28: 43860 | E28: 65000 | I28: ENTRADA | J28: IMPRESIÓN DE TIQUETES
A29: 28 | B29: =YEAR(D29) -> 2020 | C29: =MONTH(D29) -> 1 | D29: 43860 | F29: 10000 | I29: OTROS | J29: camara y comercio center cit
A30: 29 | B30: =YEAR(D30) -> 2020 | C30: =MONTH(D30) -> 1 | D30: 43860 | F30: 4000 | I30: OTROS | J30: copias
A31: 30 | B31: =YEAR(D31) -> 2020 | C31: =MONTH(D31) -> 1 | D31: 43861 | F31: 100000 | I31: TRABAJOS | J31: recarga sms
A32: 31 | B32: =YEAR(D32) -> 2020 | C32: =MONTH(D32) -> 1 | D32: 43861 | F32: 30000 | I32: SALIDAS | J32: Compra de perritos altoque
A33: 32 | B33: =YEAR(D33) -> 2020 | C33: =MONTH(D33) -> 1 | D33: 43861 | F33: 10000 | I33: COMIDA | J33: almuerzo oficina | K33: =SUM(F2:F33) -> 1759200
A34: 33 | B34: =YEAR(D34) -> 2020 | C34: =MONTH(D34) -> 2 | D34: 43862 | F34: 120000 | I34: OTROS | J34: compra zapatos niños
A35: 34 | B35: =YEAR(D35) -> 2020 | C35: =MONTH(D35) -> 2 | D35: 43862 | F35: 20000 | I35: SALIDAS | J35: compra de helado
A36: 35 | B36: =YEAR(D36) -> 2020 | C36: =MONTH(D36) -> 2 | D36: 43862 | F36: 100000 | I36: GASOLINA | J36: gasolina
A37: 36 | B37: =YEAR(D37) -> 2020 | C37: =MONTH(D37) -> 2 | D37: 43863 | F37: 20000 | I37: SALIDAS | J37: helados
A38: 37 | B38: =YEAR(D38) -> 2020 | C38: =MONTH(D38) -> 2 | D38: 43863 | F38: 50000 | I38: SALIDAS | J38: detalle cumple martha cabal
A39: 38 | B39: =YEAR(D39) -> 2020 | C39: =MONTH(D39) -> 2 | D39: 43864 | F39: 10000 | I39: COMIDA | J39: almuerzo comida
A40: 39 | B40: =YEAR(D40) -> 2020 | C40: =MONTH(D40) -> 2 | D40: 43865 | F40: 90000 | I40: COMIDA | J40: compra de mercado D1
A41: 40 | B41: =YEAR(D41) -> 2020 | C41: =MONTH(D41) -> 2 | D41: 43865 | F41: 40000 | I41: COMIDA | J41: almuerzo con madre - casuela
A42: 41 | B42: =YEAR(D42) -> 2020 | C42: =MONTH(D42) -> 2 | D42: 43870 | F42: 50000 | I42: SALIDAS | J42: salida con diana a comer sushi
A43: 42 | B43: =YEAR(D43) -> 2020 | C43: =MONTH(D43) -> 2 | D43: 43871 | F43: 150000 | J43: gastos
A44: 43 | B44: =YEAR(D44) -> 2020 | C44: =MONTH(D44) -> 2 | D44: 43873 | F44: 20000 | I44: OTROS | J44: yui comida
...

Sheet PROYECTOS
A1: No | B1: Fecha | C1: Entrada | D1: Salida | E1: Proyecto | F1: Obervacion
A2: 1 | B2: 45721 | C2: 3470000 | E2: CuentaFacil | F2: pago cuota febrero de Martin
A3: 2 | B3: 45721 | C3: 2470000 | E3: CuentaFacil | F3: pago cuota febrero de Rosero
A4: 3 | B4: 45722 | C4: - | D4: 120000 | E4: CuentaFacil | F4: pago a gisell cuentas FEBRERO
A5: 4 | B5: 45722 | C5: - | D5: 2470000 | E5: CuentaFacil | F5: para Jhon Rosero
A6: 5 | B6: 45722 | C6: - | D6: 2470000 | E6: CuentaFacil | F6: para Brayan Garcia
A7: 6 | B7: 45724 | D7: 100000 | E7: Zencorp | F7: Reunion telk
A8: 7 | B8: 45726 | D8: 3000000 | E8: CuentaFacil | F8: Compra portatil jhon Rosero
A9: 8 | B9: 45728 | C9: 7500000 | D9: - | E9: Zencorp | F9: Abono de aliados proyecto 2025
A10: 9 | B10: 45728 | C10: - | D10: 7500000 | E10: Zencorp | F10: Jhon Rosero
A11: 10 | B11: 45735 | C11: - | D11: 450000 | E11: CuentaFacil | F11: Planilla Febebrero Rosero
A12: 11 | B12: 45737 | C12: - | D12: 82000 | E12: Zencorp | F12: ChatGpt Marzo
A13: 12 | B13: 45738 | D13: 368000 | E13: Avapp | F13: Hosting Hostgator Avapp
A14: 13 | B14: 45747 | C14: 3470000 | D14: - | E14: CuentaFacil | F14: pago cuota Marzo de Martin
A15: 14 | B15: 45747 | C15: 2470000 | D15: - | E15: CuentaFacil | F15: pago cuota Marzo de Rosero
A16: 15 | B16: 45747 | C16: - | D16: 2470000 | E16: CuentaFacil | F16: para Jhon Rosero
A17: 16 | B17: 45747 | C17: - | D17: 2470000 | E17: CuentaFacil | F17: para Brayan Garcia
A18: 17 | B18: 45747 | C18: 15500000 | D18: - | E18: Zencorp | F18: Abono de aliados proyecto 2025
A19: 18 | B19: 45747 | C19: - | D19: 4000000 | E19: Zencorp | F19: Jhon Rosero
A20: 19 | B20: 45747 | C20: - | D20: 11500000 | E20: Zencorp | F20: Brayan Garcia
A21: 20 | B21: 45748 | C21: - | D21: 146000 | E21: CuentaFacil | F21: Dominio Cuentafacil.co 2 años | M21: =26/4 -> 6.5
A22: 21 | B22: 45755 | C22: 1500000 | D22: - | E22: Avapp | F22: gustavo pacto valle
A23: 22 | B23: 45777 | C23: - | D23: 450000 | E23: CuentaFacil | F23: Planilla Marzo Rosero
A24: 23 | B24: 45777 | C24: 3500000 | D24: - | E24: CuentaFacil | F24: pago cuota Abril de Martin
A25: 24 | B25: 45777 | C25: 2470000 | D25: - | E25: CuentaFacil | F25: pago cuota Abril de Rosero
A26: 25 | B26: 45777 | C26: - | D26: 2470000 | E26: CuentaFacil | F26: para Jhon Rosero
A27: 26 | B27: 45777 | C27: - | D27: 2470000 | E27: CuentaFacil | F27: para Brayan Garcia
A28: 27 | B28: 45789 | D28: 120000 | E28: CuentaFacil | F28: giselle cuentas CUENTA MARZO
A29: 28 | B29: 45798 | C29: - | D29: 450000 | E29: CuentaFacil | F29: Planilla Abril Rosero
A30: 29 | B30: 45807 | C30: 3500000 | D30: - | E30: CuentaFacil | F30: pago cuota Mayo de Martin
A31: 30 | B31: 45807 | C31: 2470000 | D31: - | E31: CuentaFacil | F31: pago cuota Mayo de Rosero
A32: 31 | B32: 45807 | C32: - | D32: 2470000 | E32: CuentaFacil | F32: para Jhon Rosero
A33: 32 | B33: 45807 | C33: - | D33: 2470000 | E33: CuentaFacil | F33: para Brayan Garcia
A34: 33 | B34: 45789 | C34: - | D34: 120000 | E34: CuentaFacil | F34: giselle cuentas CEUNTA ABRIL
A35: 34 | B35: 45832 | C35: - | D35: 450000 | E35: CuentaFacil | F35: Planilla Mayo Rosero
A36: 35 | B36: 45838 | C36: 3500000 | D36: - | E36: CuentaFacil | F36: pago cuota Junio de Martin
A37: 36 | B37: 45838 | C37: 2470000 | D37: - | E37: CuentaFacil | F37: pago cuota Junio de Rosero
A38: 37 | B38: 45838 | C38: - | D38: 2470000 | E38: CuentaFacil | F38: para Jhon Rosero
A39: 38 | B39: 45838 | C39: - | D39: 2470000 | E39: CuentaFacil | F39: para Brayan Garcia
A40: 39 | B40: 45820 | C40: - | D40: 120000 | E40: CuentaFacil | F40: giselle cuentas CEUNTA MAYO
...

Sheet APP
B1: CARLOSAPP | C1: CMJRADICAL | D1: PACTO | E1: SIEMBRA20 | K1: TOTAL MENSUAL
A2: ENERO | B2: x | D2: x | K2: =SUM(B2:J2) -> 0
A3: FEBRERO | B3: x | D3: - | K3: =SUM(B3:J3) -> 0
A4: MARZO | B4: 1500000 | D4: - | K4: =SUM(B4:J4) -> 1500000
A5: ABRIL | B5: 1000000 | D5: - | K5: =SUM(B5:J5) -> 1000000
A6: MAYO | B6: 1000000 | D6: - | K6: =SUM(B6:J6) -> 1000000
A7: JUNIO | B7: 1000000 | D7: - | K7: =SUM(B7:J7) -> 1000000
A8: JULIO | B8: 1000000 | D8: - | E8: 1000000 | K8: =SUM(B8:J8) -> 2000000
A9: AGOSTO | B9: 1000000 | C9: 1000000 | D9: 1000000 | E9: 0 | K9: =SUM(B9:J9) -> 3000000
A10: SEPTIEMBRE | B10: 1000000 | C10: 500000 | D10: 1000000 | E10: 0 | K10: =SUM(B10:J10) -> 2500000
A11: OCTUBRE | B11: 1000000 | C11: 500000 | D11: 500000 | E11: 0 | K11: =SUM(B11:J11) -> 2000000
A12: NOVIEMBRE | B12: 1000000 | C12: 0 | D12: - | E12: - | K12: =SUM(B12:J12) -> 1000000
A13: DICIEMBRE | B13: 1000000 | C13: 500000 | D13: - | E13: - | K13: =SUM(B13:J13) -> 1500000
B14: =SUM(B2:B13) -> 10500000 | C14: =SUM(C2:C13) -> 2500000 | D14: =SUM(D2:D13) -> 2500000 | E14: =SUM(E2:E13) -> 1000000 | F14: =SUM(F2:F13) -> 0 | G14: =SUM(G2:G13) -> 0 | J14: =SUM(J2:J13) -> 0 | K14: =SUM(B14:J14) -> 16500000
B18: 1523 | C18: Jovenes_lideres
B19: 2026 | C19: Jovenes_carlosapp
B20: 2250 | C20: jovenes_CMJ
B21: 17398 | C21: Ingreso Fya Carlos Hernan | J21: =54000-B21 -> 36602
A22: Envios | B22: =SUM(B18:B21) -> 23197 | C22: =B22*100 -> 2319700
B24: 7000 | C24: censo cmj
B25: 24000 | C25: censo carlosapp
A26: total | B26: =SUM(B24:B25) -> 31000 | C26: =B26*85 -> 2635000 | F26: =40000*80 -> 3200000
B29: TOTAL | C29: =B14+C22+C26+C14 -> 17954700
B34: CARLOSAPP | C34: CMJRADICAL | D34: PACTO | E34: SIEMBRA20 | F34: VARELA | G34: SOMOS C | H34: BTURA | I34: L-103 | K34: TOTAL MENSUAL
A35: ENERO | B35: 1000000 | C35: 500000 | D35: - | E35: - | F35: - | G35: - | H35: - | I35: - | K35: =SUM(B35:J35) -> 1500000
A36: FEBRERO | B36: 1000000 | C36: - | D36: - | E36: - | F36: - | G36: - | H36: - | I36: - | K36: =SUM(B36:J36) -> 1000000 | L36: 3200000
A37: MARZO | B37: 1000000 | C37: - | D37: - | E37: - | F37: - | G37: - | H37: - | I37: - | K37: =SUM(B37:J37) -> 1000000 | L37: =25000*100 -> 2500000
A38: ABRIL | B38: - | D38: - | E38: - | F38: - | G38: - | H38: - | I38: - | K38: =SUM(B38:J38) -> 0
A39: MAYO | B39: - | D39: - | E39: - | F39: - | G39: - | H39: - | I39: - | K39: =SUM(B39:J39) -> 0 | L39: =20000*80 -> 1600000
A40: JUNIO | B40: - | D40: - | E40: - | F40: - | G40: - | H40: - | I40: - | K40: =SUM(B40:J40) -> 0 | L40: =20000*100 -> 2000000
A41: JULIO | B41: - | D41: - | E41: - | F41: - | G41: - | H41: - | I41: - | K41: =SUM(B41:J41) -> 0 | M41: =30000000/60000 -> 500
A42: AGOSTO | B42: - | D42: - | E42: - | F42: - | G42: - | H42: - | I42: - | K42: =SUM(B42:J42) -> 0
A43: SEPTIEMBRE | B43: - | D43: - | E43: - | F43: - | G43: - | H43: - | I43: - | K43: =SUM(B43:J43) -> 0 | L43: =50000*100 -> 5000000
A44: OCTUBRE | B44: - | D44: - | E44: - | F44: - | G44: - | H44: - | I44: - | K44: =SUM(B44:J44) -> 0
A45: NOVIEMBRE | B45: - | D45: - | E45: - | F45: - | G45: - | H45: - | I45: - | K45: =SUM(B45:J45) -> 0
A46: DICIEMBRE | B46: - | D46: - | E46: - | F46: - | G46: - | H46: - | I46: - | K46: =SUM(B46:J46) -> 0
B47: =SUM(B35:B46) -> 3000000 | C47: =SUM(C35:C46) -> 500000 | D47: =SUM(D35:D46) -> 0 | E47: =SUM(E35:E46) -> 0 | F47: =SUM(F35:F46) -> 0 | G47: =SUM(G35:G46) -> 0 | J47: =SUM(J35:J46) -> 0 | K47: =SUM(B47:J47) -> 3500000 | M47: =K47+C29 -> 21454700
A50: 36602 X 100 | B50: =36602*100 -> 3660200 | C50: Ingreso Fya Carlos Hernan
A51: 77507 X 100 | B51: =77507*100 -> 7750700 | C51: Ingreso Fya Carlos Hernan
A52: 138027 X 80 | B52: =138027*80 -> 11042160 | C52: censo carlosapp | M52: =300 -> 300
...

Sheet INFORME GASTOS
A1: AÑO | B1: 2024
B2: 1 | C2: 2 | D2: 3 | E2: 4 | F2: 5 | G2: 6 | H2: 7 | I2: 8 | J2: 9 | K2: 10 | L2: 11 | M2: 12
A3: TIPO GASTO | B3: ENERO | C3: FEBRERO | D3: MARZO | E3: ABRIL | F3: MAYO | G3: JUNIO | H3: JULIO | I3: AGOSTO | J3: SEPTIEMBRE | K3: OCTUBRE | L3: NOVIEMBRE | M3: DICIEMBRE
A4: almuerzo | B4: =SUMIFS(GASTOS!$F:$F,GASTOS!$I:$I,'INFORME GASTOS'!$A4,GASTOS!$B:$B,$B$1,GASTOS!$C:$C,B$2) -> 469000 | C4: =SUMIFS(GASTOS!$F:$F,GASTOS!$I:$I,'INFORME GASTOS'!$A4,GASTOS!$B:$B,$B$1,GASTOS!$C:$C,C$2) -> 792000 | D4: =SUMIFS(GASTOS!$F:$F,GASTOS!$I:$I,'INFORME GASTOS'!$A4,GASTOS!$B:$B,$B$1,GASTOS!$C:$C,D$2) -> 614000 | E4: =SUMIFS(GASTOS!$F:$F,GASTOS!$I:$I,'INFORME GASTOS'!$A4,GASTOS!$B:$B,$B$1,GASTOS!$C:$C,E$2) -> 435000 | F4: =SUMIFS(GASTOS!$F:$F,GASTOS!$I:$I,'INFORME GASTOS'!$A4,GASTOS!$B:$B,$B$1,GASTOS!$C:$C,F$2) -> 580000 | G4: =SUMIFS(GASTOS!$F:$F,GASTOS!$I:$I,'INFORME GASTOS'!$A4,GASTOS!$B:$B,$B$1,GASTOS!$C:$C,G$2) -> 498000 | H4: =SUMIFS(GASTOS!$F:$F,GASTOS!$I:$I,'INFORME GASTOS'!$A4,GASTOS!$B:$B,$B$1,GASTOS!$C:$C,H$2) -> 125000 | I4: =SUMIFS(GASTOS!$F:$F,GASTOS!$I:$I,'INFORME GASTOS'!$A4,GASTOS!$B:$B,$B$1,GASTOS!$C:$C,I$2) -> 346000 | ... M4: =SUMIFS(GASTOS!$F:$F,GASTOS!$I:$I,'INFORME GASTOS'!$A4,GASTOS!$B:$B,$B$1,GASTOS!$C:$C,M$2) -> 425000
A5: MERCADO | B5: =SUMIFS(GASTOS!$F:$F,GASTOS!$I:$I,'INFORME GASTOS'!$A5,GASTOS!$B:$B,$B$1,GASTOS!$C:$C,B$2) -> 605000 | C5: =SUMIFS(GASTOS!$F:$F,GASTOS!$I:$I,'INFORME GASTOS'!$A5,GASTOS!$B:$B,$B$1,GASTOS!$C:$C,C$2) -> 580500 | D5: =SUMIFS(GASTOS!$F:$F,GASTOS!$I:$I,'INFORME GASTOS'!$A5,GASTOS!$B:$B,$B$1,GASTOS!$C:$C,D$2) -> 519000 | E5: =SUMIFS(GASTOS!$F:$F,GASTOS!$I:$I,'INFORME GASTOS'!$A5,GASTOS!$B:$B,$B$1,GASTOS!$C:$C,E$2) -> 190000 | F5: =SUMIFS(GASTOS!$F:$F,GASTOS!$I:$I,'INFORME GASTOS'!$A5,GASTOS!$B:$B,$B$1,GASTOS!$C:$C,F$2) -> 526000 | G5: =SUMIFS(GASTOS!$F:$F,GASTOS!$I:$I,'INFORME GASTOS'!$A5,GASTOS!$B:$B,$B$1,GASTOS!$C:$C,G$2) -> 469000 | H5: =SUMIFS(GASTOS!$F:$F,GASTOS!$I:$I,'INFORME GASTOS'!$A5,GASTOS!$B:$B,$B$1,GASTOS!$C:$C,H$2) -> 606000 | I5: =SUMIFS(GASTOS!$F:$F,GASTOS!$I:$I,'INFORME GASTOS'!$A5,GASTOS!$B:$B,$B$1,GASTOS!$C:$C,I$2) -> 550000 | ... M5: =SUMIFS(GASTOS!$F:$F,GASTOS!$I:$I,'INFORME GASTOS'!$A5,GASTOS!$B:$B,$B$1,GASTOS!$C:$C,M$2) -> 320000
A6: OTROS | B6: =SUMIFS(GASTOS!$F:$F,GASTOS!$I:$I,'INFORME GASTOS'!$A6,GASTOS!$B:$B,$B$1,GASTOS!$C:$C,B$2) -> 1662000 | C6: =SUMIFS(GASTOS!$F:$F,GASTOS!$I:$I,'INFORME GASTOS'!$A6,GASTOS!$B:$B,$B$1,GASTOS!$C:$C,C$2) -> 780000 | D6: =SUMIFS(GASTOS!$F:$F,GASTOS!$I:$I,'INFORME GASTOS'!$A6,GASTOS!$B:$B,$B$1,GASTOS!$C:$C,D$2) -> 1566000 | E6: =SUMIFS(GASTOS!$F:$F,GASTOS!$I:$I,'INFORME GASTOS'!$A6,GASTOS!$B:$B,$B$1,GASTOS!$C:$C,E$2) -> 929000 | F6: =SUMIFS(GASTOS!$F:$F,GASTOS!$I:$I,'INFORME GASTOS'!$A6,GASTOS!$B:$B,$B$1,GASTOS!$C:$C,F$2) -> 2589000 | G6: =SUMIFS(GASTOS!$F:$F,GASTOS!$I:$I,'INFORME GASTOS'!$A6,GASTOS!$B:$B,$B$1,GASTOS!$C:$C,G$2) -> 2800000 | H6: =SUMIFS(GASTOS!$F:$F,GASTOS!$I:$I,'INFORME GASTOS'!$A6,GASTOS!$B:$B,$B$1,GASTOS!$C:$C,H$2) -> 1192000 | I6: =SUMIFS(GASTOS!$F:$F,GASTOS!$I:$I,'INFORME GASTOS'!$A6,GASTOS!$B:$B,$B$1,GASTOS!$C:$C,I$2) -> 837000 | ... M6: =SUMIFS(GASTOS!$F:$F,GASTOS!$I:$I,'INFORME GASTOS'!$A6,GASTOS!$B:$B,$B$1,GASTOS!$C:$C,M$2) -> 3515000
A7: NIÑOS | B7: =SUMIFS(GASTOS!$F:$F,GASTOS!$I:$I,'INFORME GASTOS'!$A7,GASTOS!$B:$B,$B$1,GASTOS!$C:$C,B$2) -> 757000 | C7: =SUMIFS(GASTOS!$F:$F,GASTOS!$I:$I,'INFORME GASTOS'!$A7,GASTOS!$B:$B,$B$1,GASTOS!$C:$C,C$2) -> 823000 | D7: =SUMIFS(GASTOS!$F:$F,GASTOS!$I:$I,'INFORME GASTOS'!$A7,GASTOS!$B:$B,$B$1,GASTOS!$C:$C,D$2) -> 1248000 | E7: =SUMIFS(GASTOS!$F:$F,GASTOS!$I:$I,'INFORME GASTOS'!$A7,GASTOS!$B:$B,$B$1,GASTOS!$C:$C,E$2) -> 821000 | F7: =SUMIFS(GASTOS!$F:$F,GASTOS!$I:$I,'INFORME GASTOS'!$A7,GASTOS!$B:$B,$B$1,GASTOS!$C:$C,F$2) -> 750000 | G7: =SUMIFS(GASTOS!$F:$F,GASTOS!$I:$I,'INFORME GASTOS'!$A7,GASTOS!$B:$B,$B$1,GASTOS!$C:$C,G$2) -> 563000 | H7: =SUMIFS(GASTOS!$F:$F,GASTOS!$I:$I,'INFORME GASTOS'!$A7,GASTOS!$B:$B,$B$1,GASTOS!$C:$C,H$2) -> 662000 | I7: =SUMIFS(GASTOS!$F:$F,GASTOS!$I:$I,'INFORME GASTOS'!$A7,GASTOS!$B:$B,$B$1,GASTOS!$C:$C,I$2) -> 800000 | ... M7: =SUMIFS(GASTOS!$F:$F,GASTOS!$I:$I,'INFORME GASTOS'!$A7,GASTOS!$B:$B,$B$1,GASTOS!$C:$C,M$2) -> 2772000
A8: salidas | B8: =SUMIFS(GASTOS!$F:$F,GASTOS!$I:$I,'INFORME GASTOS'!$A8,GASTOS!$B:$B,$B$1,GASTOS!$C:$C,B$2) -> 949000 | C8: =SUMIFS(GASTOS!$F:$F,GASTOS!$I:$I,'INFORME GASTOS'!$A8,GASTOS!$B:$B,$B$1,GASTOS!$C:$C,C$2) -> 1324000 | D8: =SUMIFS(GASTOS!$F:$F,GASTOS!$I:$I,'INFORME GASTOS'!$A8,GASTOS!$B:$B,$B$1,GASTOS!$C:$C,D$2) -> 729000 | E8: =SUMIFS(GASTOS!$F:$F,GASTOS!$I:$I,'INFORME GASTOS'!$A8,GASTOS!$B:$B,$B$1,GASTOS!$C:$C,E$2) -> 1266000 | F8: =SUMIFS(GASTOS!$F:$F,GASTOS!$I:$I,'INFORME GASTOS'!$A8,GASTOS!$B:$B,$B$1,GASTOS!$C:$C,F$2) -> 996000 | G8: =SUMIFS(GASTOS!$F:$F,GASTOS!$I:$I,'INFORME GASTOS'!$A8,GASTOS!$B:$B,$B$1,GASTOS!$C:$C,G$2) -> 1210000 | H8: =SUMIFS(GASTOS!$F:$F,GASTOS!$I:$I,'INFORME GASTOS'!$A8,GASTOS!$B:$B,$B$1,GASTOS!$C:$C,H$2) -> 1220000 | I8: =SUMIFS(GASTOS!$F:$F,GASTOS!$I:$I,'INFORME GASTOS'!$A8,GASTOS!$B:$B,$B$1,GASTOS!$C:$C,I$2) -> 450000 | ... M8: =SUMIFS(GASTOS!$F:$F,GASTOS!$I:$I,'INFORME GASTOS'!$A8,GASTOS!$B:$B,$B$1,GASTOS!$C:$C,M$2) -> 60000
A9: parqueadero | B9: =SUMIFS(GASTOS!$F:$F,GASTOS!$I:$I,'INFORME GASTOS'!$A9,GASTOS!$B:$B,$B$1,GASTOS!$C:$C,B$2) -> 423000 | C9: =SUMIFS(GASTOS!$F:$F,GASTOS!$I:$I,'INFORME GASTOS'!$A9,GASTOS!$B:$B,$B$1,GASTOS!$C:$C,C$2) -> 234000 | D9: =SUMIFS(GASTOS!$F:$F,GASTOS!$I:$I,'INFORME GASTOS'!$A9,GASTOS!$B:$B,$B$1,GASTOS!$C:$C,D$2) -> 310000 | E9: =SUMIFS(GASTOS!$F:$F,GASTOS!$I:$I,'INFORME GASTOS'!$A9,GASTOS!$B:$B,$B$1,GASTOS!$C:$C,E$2) -> 274000 | F9: =SUMIFS(GASTOS!$F:$F,GASTOS!$I:$I,'INFORME GASTOS'!$A9,GASTOS!$B:$B,$B$1,GASTOS!$C:$C,F$2) -> 225000 | G9: =SUMIFS(GASTOS!$F:$F,GASTOS!$I:$I,'INFORME GASTOS'!$A9,GASTOS!$B:$B,$B$1,GASTOS!$C:$C,G$2) -> 142000 | H9: =SUMIFS(GASTOS!$F:$F,GASTOS!$I:$I,'INFORME GASTOS'!$A9,GASTOS!$B:$B,$B$1,GASTOS!$C:$C,H$2) -> 67000 | I9: =SUMIFS(GASTOS!$F:$F,GASTOS!$I:$I,'INFORME GASTOS'!$A9,GASTOS!$B:$B,$B$1,GASTOS!$C:$C,I$2) -> 74000 | ... M9: =SUMIFS(GASTOS!$F:$F,GASTOS!$I:$I,'INFORME GASTOS'!$A9,GASTOS!$B:$B,$B$1,GASTOS!$C:$C,M$2) -> 157000
A10: empresa | B10: =SUMIFS(GASTOS!$F:$F,GASTOS!$I:$I,'INFORME GASTOS'!$A10,GASTOS!$B:$B,$B$1,GASTOS!$C:$C,B$2) -> 652000 | C10: =SUMIFS(GASTOS!$F:$F,GASTOS!$I:$I,'INFORME GASTOS'!$A10,GASTOS!$B:$B,$B$1,GASTOS!$C:$C,C$2) -> 599000 | D10: =SUMIFS(GASTOS!$F:$F,GASTOS!$I:$I,'INFORME GASTOS'!$A10,GASTOS!$B:$B,$B$1,GASTOS!$C:$C,D$2) -> 456000 | E10: =SUMIFS(GASTOS!$F:$F,GASTOS!$I:$I,'INFORME GASTOS'!$A10,GASTOS!$B:$B,$B$1,GASTOS!$C:$C,E$2) -> 285000 | F10: =SUMIFS(GASTOS!$F:$F,GASTOS!$I:$I,'INFORME GASTOS'!$A10,GASTOS!$B:$B,$B$1,GASTOS!$C:$C,F$2) -> 968000 | G10: =SUMIFS(GASTOS!$F:$F,GASTOS!$I:$I,'INFORME GASTOS'!$A10,GASTOS!$B:$B,$B$1,GASTOS!$C:$C,G$2) -> 817000 | H10: =SUMIFS(GASTOS!$F:$F,GASTOS!$I:$I,'INFORME GASTOS'!$A10,GASTOS!$B:$B,$B$1,GASTOS!$C:$C,H$2) -> 341000 | I10: =SUMIFS(GASTOS!$F:$F,GASTOS!$I:$I,'INFORME GASTOS'!$A10,GASTOS!$B:$B,$B$1,GASTOS!$C:$C,I$2) -> 0 | ... M10: =SUMIFS(GASTOS!$F:$F,GASTOS!$I:$I,'INFORME GASTOS'!$A10,GASTOS!$B:$B,$B$1,GASTOS!$C:$C,M$2) -> 326000
A11: gasolina | B11: =SUMIFS(GASTOS!$F:$F,GASTOS!$I:$I,'INFORME GASTOS'!$A11,GASTOS!$B:$B,$B$1,GASTOS!$C:$C,B$2) -> 276000 | C11: =SUMIFS(GASTOS!$F:$F,GASTOS!$I:$I,'INFORME GASTOS'!$A11,GASTOS!$B:$B,$B$1,GASTOS!$C:$C,C$2) -> 637000 | D11: =SUMIFS(GASTOS!$F:$F,GASTOS!$I:$I,'INFORME GASTOS'!$A11,GASTOS!$B:$B,$B$1,GASTOS!$C:$C,D$2) -> 340000 | E11: =SUMIFS(GASTOS!$F:$F,GASTOS!$I:$I,'INFORME GASTOS'!$A11,GASTOS!$B:$B,$B$1,GASTOS!$C:$C,E$2) -> 530000 | F11: =SUMIFS(GASTOS!$F:$F,GASTOS!$I:$I,'INFORME GASTOS'!$A11,GASTOS!$B:$B,$B$1,GASTOS!$C:$C,F$2) -> 365000 | G11: =SUMIFS(GASTOS!$F:$F,GASTOS!$I:$I,'INFORME GASTOS'!$A11,GASTOS!$B:$B,$B$1,GASTOS!$C:$C,G$2) -> 417000 | H11: =SUMIFS(GASTOS!$F:$F,GASTOS!$I:$I,'INFORME GASTOS'!$A11,GASTOS!$B:$B,$B$1,GASTOS!$C:$C,H$2) -> 387000 | I11: =SUMIFS(GASTOS!$F:$F,GASTOS!$I:$I,'INFORME GASTOS'!$A11,GASTOS!$B:$B,$B$1,GASTOS!$C:$C,I$2) -> 590000 | ... M11: =SUMIFS(GASTOS!$F:$F,GASTOS!$I:$I,'INFORME GASTOS'!$A11,GASTOS!$B:$B,$B$1,GASTOS!$C:$C,M$2) -> 620000
A12: isabella | B12: =SUMIFS(GASTOS!$F:$F,GASTOS!$I:$I,'INFORME GASTOS'!$A12,GASTOS!$B:$B,$B$1,GASTOS!$C:$C,B$2) -> 1918000 | C12: =SUMIFS(GASTOS!$F:$F,GASTOS!$I:$I,'INFORME GASTOS'!$A12,GASTOS!$B:$B,$B$1,GASTOS!$C:$C,C$2) -> 0 | D12: =SUMIFS(GASTOS!$F:$F,GASTOS!$I:$I,'INFORME GASTOS'!$A12,GASTOS!$B:$B,$B$1,GASTOS!$C:$C,D$2) -> 328000 | E12: =SUMIFS(GASTOS!$F:$F,GASTOS!$I:$I,'INFORME GASTOS'!$A12,GASTOS!$B:$B,$B$1,GASTOS!$C:$C,E$2) -> 150000 | F12: =SUMIFS(GASTOS!$F:$F,GASTOS!$I:$I,'INFORME GASTOS'!$A12,GASTOS!$B:$B,$B$1,GASTOS!$C:$C,F$2) -> 32000 | G12: =SUMIFS(GASTOS!$F:$F,GASTOS!$I:$I,'INFORME GASTOS'!$A12,GASTOS!$B:$B,$B$1,GASTOS!$C:$C,G$2) -> 24000 | H12: =SUMIFS(GASTOS!$F:$F,GASTOS!$I:$I,'INFORME GASTOS'!$A12,GASTOS!$B:$B,$B$1,GASTOS!$C:$C,H$2) -> 120000 | I12: =SUMIFS(GASTOS!$F:$F,GASTOS!$I:$I,'INFORME GASTOS'!$A12,GASTOS!$B:$B,$B$1,GASTOS!$C:$C,I$2) -> 331000 | ... M12: =SUMIFS(GASTOS!$F:$F,GASTOS!$I:$I,'INFORME GASTOS'!$A12,GASTOS!$B:$B,$B$1,GASTOS!$C:$C,M$2) -> 89000
A13: IGLESIA | B13: =SUMIFS(GASTOS!$F:$F,GASTOS!$I:$I,'INFORME GASTOS'!$A13,GASTOS!$B:$B,$B$1,GASTOS!$C:$C,B$2) -> 600000 | C13: =SUMIFS(GASTOS!$F:$F,GASTOS!$I:$I,'INFORME GASTOS'!$A13,GASTOS!$B:$B,$B$1,GASTOS!$C:$C,C$2) -> 1000000 | D13: =SUMIFS(GASTOS!$F:$F,GASTOS!$I:$I,'INFORME GASTOS'!$A13,GASTOS!$B:$B,$B$1,GASTOS!$C:$C,D$2) -> 700000 | E13: =SUMIFS(GASTOS!$F:$F,GASTOS!$I:$I,'INFORME GASTOS'!$A13,GASTOS!$B:$B,$B$1,GASTOS!$C:$C,E$2) -> 0 | F13: =SUMIFS(GASTOS!$F:$F,GASTOS!$I:$I,'INFORME GASTOS'!$A13,GASTOS!$B:$B,$B$1,GASTOS!$C:$C,F$2) -> 700000 | G13: =SUMIFS(GASTOS!$F:$F,GASTOS!$I:$I,'INFORME GASTOS'!$A13,GASTOS!$B:$B,$B$1,GASTOS!$C:$C,G$2) -> 0 | H13: =SUMIFS(GASTOS!$F:$F,GASTOS!$I:$I,'INFORME GASTOS'!$A13,GASTOS!$B:$B,$B$1,GASTOS!$C:$C,H$2) -> 700000 | I13: =SUMIFS(GASTOS!$F:$F,GASTOS!$I:$I,'INFORME GASTOS'!$A13,GASTOS!$B:$B,$B$1,GASTOS!$C:$C,I$2) -> 700000 | ... M13: =SUMIFS(GASTOS!$F:$F,GASTOS!$I:$I,'INFORME GASTOS'!$A13,GASTOS!$B:$B,$B$1,GASTOS!$C:$C,M$2) -> 1000000
A14: cadena | B14: =SUMIFS(GASTOS!$F:$F,GASTOS!$I:$I,'INFORME GASTOS'!$A14,GASTOS!$B:$B,$B$1,GASTOS!$C:$C,B$2) -> 250000 | C14: =SUMIFS(GASTOS!$F:$F,GASTOS!$I:$I,'INFORME GASTOS'!$A14,GASTOS!$B:$B,$B$1,GASTOS!$C:$C,C$2) -> 250000 | D14: =SUMIFS(GASTOS!$F:$F,GASTOS!$I:$I,'INFORME GASTOS'!$A14,GASTOS!$B:$B,$B$1,GASTOS!$C:$C,D$2) -> 250000 | E14: =SUMIFS(GASTOS!$F:$F,GASTOS!$I:$I,'INFORME GASTOS'!$A14,GASTOS!$B:$B,$B$1,GASTOS!$C:$C,E$2) -> 250000 | F14: =SUMIFS(GASTOS!$F:$F,GASTOS!$I:$I,'INFORME GASTOS'!$A14,GASTOS!$B:$B,$B$1,GASTOS!$C:$C,F$2) -> 250000 | G14: =SUMIFS(GASTOS!$F:$F,GASTOS!$I:$I,'INFORME GASTOS'!$A14,GASTOS!$B:$B,$B$1,GASTOS!$C:$C,G$2) -> 250000 | H14: =SUMIFS(GASTOS!$F:$F,GASTOS!$I:$I,'INFORME GASTOS'!$A14,GASTOS!$B:$B,$B$1,GASTOS!$C:$C,H$2) -> 250000 | I14: =SUMIFS(GASTOS!$F:$F,GASTOS!$I:$I,'INFORME GASTOS'!$A14,GASTOS!$B:$B,$B$1,GASTOS!$C:$C,I$2) -> 250000 | ... M14: =SUMIFS(GASTOS!$F:$F,GASTOS!$I:$I,'INFORME GASTOS'!$A14,GASTOS!$B:$B,$B$1,GASTOS!$C:$C,M$2) -> 0
A15: ASEO | B15: =SUMIFS(GASTOS!$F:$F,GASTOS!$I:$I,'INFORME GASTOS'!$A15,GASTOS!$B:$B,$B$1,GASTOS!$C:$C,B$2) -> 50000 | C15: =SUMIFS(GASTOS!$F:$F,GASTOS!$I:$I,'INFORME GASTOS'!$A15,GASTOS!$B:$B,$B$1,GASTOS!$C:$C,C$2) -> 40000 | D15: =SUMIFS(GASTOS!$F:$F,GASTOS!$I:$I,'INFORME GASTOS'!$A15,GASTOS!$B:$B,$B$1,GASTOS!$C:$C,D$2) -> 247500 | E15: =SUMIFS(GASTOS!$F:$F,GASTOS!$I:$I,'INFORME GASTOS'!$A15,GASTOS!$B:$B,$B$1,GASTOS!$C:$C,E$2) -> 220000 | F15: =SUMIFS(GASTOS!$F:$F,GASTOS!$I:$I,'INFORME GASTOS'!$A15,GASTOS!$B:$B,$B$1,GASTOS!$C:$C,F$2) -> 80000 | G15: =SUMIFS(GASTOS!$F:$F,GASTOS!$I:$I,'INFORME GASTOS'!$A15,GASTOS!$B:$B,$B$1,GASTOS!$C:$C,G$2) -> 60000 | H15: =SUMIFS(GASTOS!$F:$F,GASTOS!$I:$I,'INFORME GASTOS'!$A15,GASTOS!$B:$B,$B$1,GASTOS!$C:$C,H$2) -> 50000 | I15: =SUMIFS(GASTOS!$F:$F,GASTOS!$I:$I,'INFORME GASTOS'!$A15,GASTOS!$B:$B,$B$1,GASTOS!$C:$C,I$2) -> 0 | ... M15: =SUMIFS(GASTOS!$F:$F,GASTOS!$I:$I,'INFORME GASTOS'!$A15,GASTOS!$B:$B,$B$1,GASTOS!$C:$C,M$2) -> 0
... A21: ENTRADA | B21: =SUMIFS(GASTOS!$F:$F,GASTOS!$I:$I,'INFORME GASTOS'!$A21,GASTOS!$B:$B,$B$1,GASTOS!$C:$C,B$2) -> 0 | C21: =SUMIFS(GASTOS!$F:$F,GASTOS!$I:$I,'INFORME GASTOS'!$A21,GASTOS!$B:$B,$B$1,GASTOS!$C:$C,C$2) -> 0 | D21: =SUMIFS(GASTOS!$F:$F,GASTOS!$I:$I,'INFORME GASTOS'!$A21,GASTOS!$B:$B,$B$1,GASTOS!$C:$C,D$2) -> 0 | E21: =SUMIFS(GASTOS!$F:$F,GASTOS!$I:$I,'INFORME GASTOS'!$A21,GASTOS!$B:$B,$B$1,GASTOS!$C:$C,E$2) -> 0 | F21: =SUMIFS(GASTOS!$F:$F,GASTOS!$I:$I,'INFORME GASTOS'!$A21,GASTOS!$B:$B,$B$1,GASTOS!$C:$C,F$2) -> 0 | G21: =SUMIFS(GASTOS!$F:$F,GASTOS!$I:$I,'INFORME GASTOS'!$A21,GASTOS!$B:$B,$B$1,GASTOS!$C:$C,G$2) -> 0 | H21: =SUMIFS(GASTOS!$F:$F,GASTOS!$I:$I,'INFORME GASTOS'!$A21,GASTOS!$B:$B,$B$1,GASTOS!$C:$C,H$2) -> 0 | I21: =SUMIFS(GASTOS!$F:$F,GASTOS!$I:$I,'INFORME GASTOS'!$A21,GASTOS!$B:$B,$B$1,GASTOS!$C:$C,I$2) -> 0 | ... M21: =SUMIFS(GASTOS!$F:$F,GASTOS!$I:$I,'INFORME GASTOS'!$A21,GASTOS!$B:$B,$B$1,GASTOS!$C:$C,M$2) -> 0
B22: =SUM(B5:B21) -> 8503200 | C22: =SUM(C5:C21) -> 6671000 | D22: =SUM(D5:D21) -> 6892500 | E22: =SUM(E5:E21) -> 5383000 | F22: =SUM(F5:F21) -> 7711000 | G22: =SUM(G5:G21) -> 6805000 | H22: =SUM(H5:H21) -> 6599000 | I22: =SUM(I5:I21) -> 5310600 | ... M22: =SUM(M5:M21) -> 10011000
A25: AÑO | B25: 2026
B26: 1 | C26: 2 | D26: 3 | E26: 4 | F26: 5 | G26: 6 | H26: 7 | I26: 8 | J26: 9 | K26: 10 | L26: 11 | M26: 12
A27: TIPO GASTO | B27: ENERO | C27: FEBRERO | D27: MARZO | E27: ABRIL | F27: MAYO | G27: JUNIO | H27: JULIO | I27: AGOSTO | J27: SEPTIEMBRE | K27: OCTUBRE | L27: NOVIEMBRE | M27: DICIEMBRE
A28: almuerzo | B28: =SUMIFS(GASTOS!$F:$F,GASTOS!$I:$I,'INFORME GASTOS'!$A28,GASTOS!$B:$B,$B$25,GASTOS!$C:$C,B$2) -> 638000 | C28: =SUMIFS(GASTOS!$F:$F,GASTOS!$I:$I,'INFORME GASTOS'!$A28,GASTOS!$B:$B,$B$25,GASTOS!$C:$C,C$2) -> 584000 | D28: =SUMIFS(GASTOS!$F:$F,GASTOS!$I:$I,'INFORME GASTOS'!$A28,GASTOS!$B:$B,$B$25,GASTOS!$C:$C,D$2) -> 309000 | E28: =SUMIFS(GASTOS!$F:$F,GASTOS!$I:$I,'INFORME GASTOS'!$A28,GASTOS!$B:$B,$B$25,GASTOS!$C:$C,E$2) -> 210000 | F28: =SUMIFS(GASTOS!$F:$F,GASTOS!$I:$I,'INFORME GASTOS'!$A28,GASTOS!$B:$B,$B$25,GASTOS!$C:$C,F$2) -> 1249000 | G28: =SUMIFS(GASTOS!$F:$F,GASTOS!$I:$I,'INFORME GASTOS'!$A28,GASTOS!$B:$B,$B$25,GASTOS!$C:$C,G$2) -> 116000 | H28: =SUMIFS(GASTOS!$F:$F,GASTOS!$I:$I,'INFORME GASTOS'!$A28,GASTOS!$B:$B,$B$25,GASTOS!$C:$C,H$2) -> 0 | I28: =SUMIFS(GASTOS!$F:$F,GASTOS!$I:$I,'INFORME GASTOS'!$A28,GASTOS!$B:$B,$B$25,GASTOS!$C:$C,I$2) -> 0 | ... M28: =SUMIFS(GASTOS!$F:$F,GASTOS!$I:$I,'INFORME GASTOS'!$A28,GASTOS!$B:$B,$B$25,GASTOS!$C:$C,M$2) -> 725000
A29: MERCADO | B29: =SUMIFS(GASTOS!$F:$F,GASTOS!$I:$I,'INFORME GASTOS'!$A29,GASTOS!$B:$B,$B$25,GASTOS!$C:$C,B$2) -> 1430000 | C29: =SUMIFS(GASTOS!$F:$F,GASTOS!$I:$I,'INFORME GASTOS'!$A29,GASTOS!$B:$B,$B$25,GASTOS!$C:$C,C$2) -> 0 | D29: =SUMIFS(GASTOS!$F:$F,GASTOS!$I:$I,'INFORME GASTOS'!$A29,GASTOS!$B:$B,$B$25,GASTOS!$C:$C,D$2) -> 972000 | E29: =SUMIFS(GASTOS!$F:$F,GASTOS!$I:$I,'INFORME GASTOS'!$A29,GASTOS!$B:$B,$B$25,GASTOS!$C:$C,E$2) -> 1856000 | F29: =SUMIFS(GASTOS!$F:$F,GASTOS!$I:$I,'INFORME GASTOS'!$A29,GASTOS!$B:$B,$B$25,GASTOS!$C:$C,F$2) -> 678000 | G29: =SUMIFS(GASTOS!$F:$F,GASTOS!$I:$I,'INFORME GASTOS'!$A29,GASTOS!$B:$B,$B$25,GASTOS!$C:$C,G$2) -> 728000 | H29: =SUMIFS(GASTOS!$F:$F,GASTOS!$I:$I,'INFORME GASTOS'!$A29,GASTOS!$B:$B,$B$25,GASTOS!$C:$C,H$2) -> 0 | I29: =SUMIFS(GASTOS!$F:$F,GASTOS!$I:$I,'INFORME GASTOS'!$A29,GASTOS!$B:$B,$B$25,GASTOS!$C:$C,I$2) -> 0 | ... M29: =SUMIFS(GASTOS!$F:$F,GASTOS!$I:$I,'INFORME GASTOS'!$A29,GASTOS!$B:$B,$B$25,GASTOS!$C:$C,M$2) -> 680000
A30: OTROS | B30: =SUMIFS(GASTOS!$F:$F,GASTOS!$I:$I,'INFORME GASTOS'!$A30,GASTOS!$B:$B,$B$25,GASTOS!$C:$C,B$2) -> 1158000 | C30: =SUMIFS(GASTOS!$F:$F,GASTOS!$I:$I,'INFORME GASTOS'!$A30,GASTOS!$B:$B,$B$25,GASTOS!$C:$C,C$2) -> 6830000 | D30: =SUMIFS(GASTOS!$F:$F,GASTOS!$I:$I,'INFORME GASTOS'!$A30,GASTOS!$B:$B,$B$25,GASTOS!$C:$C,D$2) -> 7198000 | E30: =SUMIFS(GASTOS!$F:$F,GASTOS!$I:$I,'INFORME GASTOS'!$A30,GASTOS!$B:$B,$B$25,GASTOS!$C:$C,E$2) -> 3603000 | F30: =SUMIFS(GASTOS!$F:$F,GASTOS!$I:$I,'INFORME GASTOS'!$A30,GASTOS!$B:$B,$B$25,GASTOS!$C:$C,F$2) -> 1753000 | G30: =SUMIFS(GASTOS!$F:$F,GASTOS!$I:$I,'INFORME GASTOS'!$A30,GASTOS!$B:$B,$B$25,GASTOS!$C:$C,G$2) -> 1389000 | H30: =SUMIFS(GASTOS!$F:$F,GASTOS!$I:$I,'INFORME GASTOS'!$A30,GASTOS!$B:$B,$B$25,GASTOS!$C:$C,H$2) -> 0 | I30: =SUMIFS(GASTOS!$F:$F,GASTOS!$I:$I,'INFORME GASTOS'!$A30,GASTOS!$B:$B,$B$25,GASTOS!$C:$C,I$2) -> 0 | ... M30: =SUMIFS(GASTOS!$F:$F,GASTOS!$I:$I,'INFORME GASTOS'!$A30,GASTOS!$B:$B,$B$25,GASTOS!$C:$C,M$2) -> 6073000
A31: NIÑOS | B31: =SUMIFS(GASTOS!$F:$F,GASTOS!$I:$I,'INFORME GASTOS'!$A31,GASTOS!$B:$B,$B$25,GASTOS!$C:$C,B$2) -> 1198000 | C31: =SUMIFS(GASTOS!$F:$F,GASTOS!$I:$I,'INFORME GASTOS'!$A31,GASTOS!$B:$B,$B$25,GASTOS!$C:$C,C$2) -> 480000 | D31: =SUMIFS(GASTOS!$F:$F,GASTOS!$I:$I,'INFORME GASTOS'!$A31,GASTOS!$B:$B,$B$25,GASTOS!$C:$C,D$2) -> 0 | E31: =SUMIFS(GASTOS!$F:$F,GASTOS!$I:$I,'INFORME GASTOS'!$A31,GASTOS!$B:$B,$B$25,GASTOS!$C:$C,E$2) -> 1050000 | F31: =SUMIFS(GASTOS!$F:$F,GASTOS!$I:$I,'INFORME GASTOS'!$A31,GASTOS!$B:$B,$B$25,GASTOS!$C:$C,F$2) -> 697000 | G31: =SUMIFS(GASTOS!$F:$F,GASTOS!$I:$I,'INFORME GASTOS'!$A31,GASTOS!$B:$B,$B$25,GASTOS!$C:$C,G$2) -> 1070000 | H31: =SUMIFS(GASTOS!$F:$F,GASTOS!$I:$I,'INFORME GASTOS'!$A31,GASTOS!$B:$B,$B$25,GASTOS!$C:$C,H$2) -> 0 | I31: =SUMIFS(GASTOS!$F:$F,GASTOS!$I:$I,'INFORME GASTOS'!$A31,GASTOS!$B:$B,$B$25,GASTOS!$C:$C,I$2) -> 0 | ... M31: =SUMIFS(GASTOS!$F:$F,GASTOS!$I:$I,'INFORME GASTOS'!$A31,GASTOS!$B:$B,$B$25,GASTOS!$C:$C,M$2) -> 2114000
A32: salidas | B32: =SUMIFS(GASTOS!$F:$F,GASTOS!$I:$I,'INFORME GASTOS'!$A32,GASTOS!$B:$B,$B$25,GASTOS!$C:$C,B$2) -> 457000 | C32: =SUMIFS(GASTOS!$F:$F,GASTOS!$I:$I,'INFORME GASTOS'!$A32,GASTOS!$B:$B,$B$25,GASTOS!$C:$C,C$2) -> 205000 | D32: =SUMIFS(GASTOS!$F:$F,GASTOS!$I:$I,'INFORME GASTOS'!$A32,GASTOS!$B:$B,$B$25,GASTOS!$C:$C,D$2) -> 109000 | E32: =SUMIFS(GASTOS!$F:$F,GASTOS!$I:$I,'INFORME GASTOS'!$A32,GASTOS!$B:$B,$B$25,GASTOS!$C:$C,E$2) -> 550000 | F32: =SUMIFS(GASTOS!$F:$F,GASTOS!$I:$I,'INFORME GASTOS'!$A32,GASTOS!$B:$B,$B$25,GASTOS!$C:$C,F$2) -> 679000 | G32: =SUMIFS(GASTOS!$F:$F,GASTOS!$I:$I,'INFORME GASTOS'!$A32,GASTOS!$B:$B,$B$25,GASTOS!$C:$C,G$2) -> 340000 | H32: =SUMIFS(GASTOS!$F:$F,GASTOS!$I:$I,'INFORME GASTOS'!$A32,GASTOS!$B:$B,$B$25,GASTOS!$C:$C,H$2) -> 0 | I32: =SUMIFS(GASTOS!$F:$F,GASTOS!$I:$I,'INFORME GASTOS'!$A32,GASTOS!$B:$B,$B$25,GASTOS!$C:$C,I$2) -> 0 | ... M32: =SUMIFS(GASTOS!$F:$F,GASTOS!$I:$I,'INFORME GASTOS'!$A32,GASTOS!$B:$B,$B$25,GASTOS!$C:$C,M$2) -> 1684000
A33: parqueadero | B33: =SUMIFS(GASTOS!$F:$F,GASTOS!$I:$I,'INFORME GASTOS'!$A33,GASTOS!$B:$B,$B$25,GASTOS!$C:$C,B$2) -> 24000 | C33: =SUMIFS(GASTOS!$F:$F,GASTOS!$I:$I,'INFORME GASTOS'!$A33,GASTOS!$B:$B,$B$25,GASTOS!$C:$C,C$2) -> 173000 | D33: =SUMIFS(GASTOS!$F:$F,GASTOS!$I:$I,'INFORME GASTOS'!$A33,GASTOS!$B:$B,$B$25,GASTOS!$C:$C,D$2) -> 0 | E33: =SUMIFS(GASTOS!$F:$F,GASTOS!$I:$I,'INFORME GASTOS'!$A33,GASTOS!$B:$B,$B$25,GASTOS!$C:$C,E$2) -> 0 | F33: =SUMIFS(GASTOS!$F:$F,GASTOS!$I:$I,'INFORME GASTOS'!$A33,GASTOS!$B:$B,$B$25,GASTOS!$C:$C,F$2) -> 0 | G33: =SUMIFS(GASTOS!$F:$F,GASTOS!$I:$I,'INFORME GASTOS'!$A33,GASTOS!$B:$B,$B$25,GASTOS!$C:$C,G$2) -> 0 | H33: =SUMIFS(GASTOS!$F:$F,GASTOS!$I:$I,'INFORME GASTOS'!$A33,GASTOS!$B:$B,$B$25,GASTOS!$C:$C,H$2) -> 0 | I33: =SUMIFS(GASTOS!$F:$F,GASTOS!$I:$I,'INFORME GASTOS'!$A33,GASTOS!$B:$B,$B$25,GASTOS!$C:$C,I$2) -> 0 | ... M33: =SUMIFS(GASTOS!$F:$F,GASTOS!$I:$I,'INFORME GASTOS'!$A33,GASTOS!$B:$B,$B$25,GASTOS!$C:$C,M$2) -> 96000
A34: empresa | B34: =SUMIFS(GASTOS!$F:$F,GASTOS!$I:$I,'INFORME GASTOS'!$A34,GASTOS!$B:$B,$B$25,GASTOS!$C:$C,B$2) -> 1833000 | C34: =SUMIFS(GASTOS!$F:$F,GASTOS!$I:$I,'INFORME GASTOS'!$A34,GASTOS!$B:$B,$B$25,GASTOS!$C:$C,C$2) -> 1044000 | D34: =SUMIFS(GASTOS!$F:$F,GASTOS!$I:$I,'INFORME GASTOS'!$A34,GASTOS!$B:$B,$B$25,GASTOS!$C:$C,D$2) -> 0 | E34: =SUMIFS(GASTOS!$F:$F,GASTOS!$I:$I,'INFORME GASTOS'!$A34,GASTOS!$B:$B,$B$25,GASTOS!$C:$C,E$2) -> 800000 | F34: =SUMIFS(GASTOS!$F:$F,GASTOS!$I:$I,'INFORME GASTOS'!$A34,GASTOS!$B:$B,$B$25,GASTOS!$C:$C,F$2) -> 2390000 | G34: =SUMIFS(GASTOS!$F:$F,GASTOS!$I:$I,'INFORME GASTOS'!$A34,GASTOS!$B:$B,$B$25,GASTOS!$C:$C,G$2) -> 353000 | H34: =SUMIFS(GASTOS!$F:$F,GASTOS!$I:$I,'INFORME GASTOS'!$A34,GASTOS!$B:$B,$B$25,GASTOS!$C:$C,H$2) -> 0 | I34: =SUMIFS(GASTOS!$F:$F,GASTOS!$I:$I,'INFORME GASTOS'!$A34,GASTOS!$B:$B,$B$25,GASTOS!$C:$C,I$2) -> 0 | ... M34: =SUMIFS(GASTOS!$F:$F,GASTOS!$I:$I,'INFORME GASTOS'!$A34,GASTOS!$B:$B,$B$25,GASTOS!$C:$C,M$2) -> 5915000
A35: gasolina | B35: =SUMIFS(GASTOS!$F:$F,GASTOS!$I:$I,'INFORME GASTOS'!$A35,GASTOS!$B:$B,$B$25,GASTOS!$C:$C,B$2) -> 420000 | C35: =SUMIFS(GASTOS!$F:$F,GASTOS!$I:$I,'INFORME GASTOS'!$A35,GASTOS!$B:$B,$B$25,GASTOS!$C:$C,C$2) -> 206000 | D35: =SUMIFS(GASTOS!$F:$F,GASTOS!$I:$I,'INFORME GASTOS'!$A35,GASTOS!$B:$B,$B$25,GASTOS!$C:$C,D$2) -> 426000 | E35: =SUMIFS(GASTOS!$F:$F,GASTOS!$I:$I,'INFORME GASTOS'!$A35,GASTOS!$B:$B,$B$25,GASTOS!$C:$C,E$2) -> 200000 | F35: =SUMIFS(GASTOS!$F:$F,GASTOS!$I:$I,'INFORME GASTOS'!$A35,GASTOS!$B:$B,$B$25,GASTOS!$C:$C,F$2) -> 435000 | G35: =SUMIFS(GASTOS!$F:$F,GASTOS!$I:$I,'INFORME GASTOS'!$A35,GASTOS!$B:$B,$B$25,GASTOS!$C:$C,G$2) -> 230000 | H35: =SUMIFS(GASTOS!$F:$F,GASTOS!$I:$I,'INFORME GASTOS'!$A35,GASTOS!$B:$B,$B$25,GASTOS!$C:$C,H$2) -> 0 | I35: =SUMIFS(GASTOS!$F:$F,GASTOS!$I:$I,'INFORME GASTOS'!$A35,GASTOS!$B:$B,$B$25,GASTOS!$C:$C,I$2) -> 0 | ... M35: =SUMIFS(GASTOS!$F:$F,GASTOS!$I:$I,'INFORME GASTOS'!$A35,GASTOS!$B:$B,$B$25,GASTOS!$C:$C,M$2) -> 470000
A36: isabella | B36: =SUMIFS(GASTOS!$F:$F,GASTOS!$I:$I,'INFORME GASTOS'!$A36,GASTOS!$B:$B,$B$25,GASTOS!$C:$C,B$2) -> 420000 | C36: =SUMIFS(GASTOS!$F:$F,GASTOS!$I:$I,'INFORME GASTOS'!$A36,GASTOS!$B:$B,$B$25,GASTOS!$C:$C,C$2) -> 0 | D36: =SUMIFS(GASTOS!$F:$F,GASTOS!$I:$I,'INFORME GASTOS'!$A36,GASTOS!$B:$B,$B$25,GASTOS!$C:$C,D$2) -> 0 | E36: =SUMIFS(GASTOS!$F:$F,GASTOS!$I:$I,'INFORME GASTOS'!$A36,GASTOS!$B:$B,$B$25,GASTOS!$C:$C,E$2) -> 100000 | F36: =SUMIFS(GASTOS!$F:$F,GASTOS!$I:$I,'INFORME GASTOS'!$A36,GASTOS!$B:$B,$B$25,GASTOS!$C:$C,F$2) -> 0 | G36: =SUMIFS(GASTOS!$F:$F,GASTOS!$I:$I,'INFORME GASTOS'!$A36,GASTOS!$B:$B,$B$25,GASTOS!$C:$C,G$2) -> 0 | H36: =SUMIFS(GASTOS!$F:$F,GASTOS!$I:$I,'INFORME GASTOS'!$A36,GASTOS!$B:$B,$B$25,GASTOS!$C:$C,H$2) -> 0 | I36: =SUMIFS(GASTOS!$F:$F,GASTOS!$I:$I,'INFORME GASTOS'!$A36,GASTOS!$B:$B,$B$25,GASTOS!$C:$C,I$2) -> 0 | ... M36: =SUMIFS(GASTOS!$F:$F,GASTOS!$I:$I,'INFORME GASTOS'!$A36,GASTOS!$B:$B,$B$25,GASTOS!$C:$C,M$2) -> 0
A37: IGLESIA | B37: =SUMIFS(GASTOS!$F:$F,GASTOS!$I:$I,'INFORME GASTOS'!$A37,GASTOS!$B:$B,$B$25,GASTOS!$C:$C,B$2) -> 0 | C37: =SUMIFS(GASTOS!$F:$F,GASTOS!$I:$I,'INFORME GASTOS'!$A37,GASTOS!$B:$B,$B$25,GASTOS!$C:$C,C$2) -> 500000 | D37: =SUMIFS(GASTOS!$F:$F,GASTOS!$I:$I,'INFORME GASTOS'!$A37,GASTOS!$B:$B,$B$25,GASTOS!$C:$C,D$2) -> 0 | E37: =SUMIFS(GASTOS!$F:$F,GASTOS!$I:$I,'INFORME GASTOS'!$A37,GASTOS!$B:$B,$B$25,GASTOS!$C:$C,E$2) -> 0 | F37: =SUMIFS(GASTOS!$F:$F,GASTOS!$I:$I,'INFORME GASTOS'!$A37,GASTOS!$B:$B,$B$25,GASTOS!$C:$C,F$2) -> 0 | G37: =SUMIFS(GASTOS!$F:$F,GASTOS!$I:$I,'INFORME GASTOS'!$A37,GASTOS!$B:$B,$B$25,GASTOS!$C:$C,G$2) -> 0 | H37: =SUMIFS(GASTOS!$F:$F,GASTOS!$I:$I,'INFORME GASTOS'!$A37,GASTOS!$B:$B,$B$25,GASTOS!$C:$C,H$2) -> 0 | I37: =SUMIFS(GASTOS!$F:$F,GASTOS!$I:$I,'INFORME GASTOS'!$A37,GASTOS!$B:$B,$B$25,GASTOS!$C:$C,I$2) -> 0 | ... M37: =SUMIFS(GASTOS!$F:$F,GASTOS!$I:$I,'INFORME GASTOS'!$A37,GASTOS!$B:$B,$B$25,GASTOS!$C:$C,M$2) -> 100000
A38: cadena | B38: =SUMIFS(GASTOS!$F:$F,GASTOS!$I:$I,'INFORME GASTOS'!$A38,GASTOS!$B:$B,$B$25,GASTOS!$C:$C,B$2) -> 0 | C38: =SUMIFS(GASTOS!$F:$F,GASTOS!$I:$I,'INFORME GASTOS'!$A38,GASTOS!$B:$B,$B$25,GASTOS!$C:$C,C$2) -> 0 | D38: =SUMIFS(GASTOS!$F:$F,GASTOS!$I:$I,'INFORME GASTOS'!$A38,GASTOS!$B:$B,$B$25,GASTOS!$C:$C,D$2) -> 0 | E38: =SUMIFS(GASTOS!$F:$F,GASTOS!$I:$I,'INFORME GASTOS'!$A38,GASTOS!$B:$B,$B$25,GASTOS!$C:$C,E$2) -> 0 | F38: =SUMIFS(GASTOS!$F:$F,GASTOS!$I:$I,'INFORME GASTOS'!$A38,GASTOS!$B:$B,$B$25,GASTOS!$C:$C,F$2) -> 0 | G38: =SUMIFS(GASTOS!$F:$F,GASTOS!$I:$I,'INFORME GASTOS'!$A38,GASTOS!$B:$B,$B$25,GASTOS!$C:$C,G$2) -> 0 | H38: =SUMIFS(GASTOS!$F:$F,GASTOS!$I:$I,'INFORME GASTOS'!$A38,GASTOS!$B:$B,$B$25,GASTOS!$C:$C,H$2) -> 0 | I38: =SUMIFS(GASTOS!$F:$F,GASTOS!$I:$I,'INFORME GASTOS'!$A38,GASTOS!$B:$B,$B$25,GASTOS!$C:$C,I$2) -> 0 | ... M38: =SUMIFS(GASTOS!$F:$F,GASTOS!$I:$I,'INFORME GASTOS'!$A38,GASTOS!$B:$B,$B$25,GASTOS!$C:$C,M$2) -> 0
